Workbook

Sheet Diretrizes
B2: Ciclos | C2: Ciclo 1 | D2: Ciclo 2 | E2: Ciclo 3 | F2: Ciclo 4 | G2: Ciclo 5 | I2: Banca Inicial | J2: Entradas/Obj*
B3: Stake Inicial de Cada Ciclo | C3: =I3 -> 100 | D3: =I3 -> 100 | E3: 125 | F3: =E7-E10 -> 137.5 | G3: =F7-F10 -> 156.25 | I3: 100 | J3: 12
B4: Objetivo jogo por jogo | C4: =$I$6 -> 0.04 | D4: =$I$6 -> 0.04 | E4: =$I$6 -> 0.04 | F4: =$I$6 -> 0.04 | G4: =$I$6 -> 0.04
B5: Fator de redução | C5: =J6 -> 0 | D5: =J6 -> 0 | E5: =J6 -> 0 | F5: =J6 -> 0 | G5: =J6 -> 0 | I5: Obj. Jogo 1 | J5: Fator de red.
B6: Parar com % de lucro | C6: 0.5 | D6: 0.5 | E6: 0.5 | F6: 0.5 | G6: 0.5 | I6: 0.04 | J6: 0
B7: Objetivo do Ciclo Chegar ate: | C7: =C3*(1+C6) -> 150 | D7: =D3*(1+D6) -> 150 | E7: =E3*(1+E6) -> 187.5 | F7: =F3*(1+F6) -> 206.25 | G7: =G3*(1+G6) -> 234.375
B8: Saldo Atual do Ciclo | C8: =if('Ciclo 1'!G3="",0,'Ciclo 1'!Q6) -> 0 | D8: =if('Ciclo 2'!G3="",0,'Ciclo 1'!Q6) -> 0 | E8: =if('Ciclo 3'!G3="",0,'Ciclo 1'!Q6) -> 0 | F8: =if('Ciclo 4'!G3="",0,'Ciclo 1'!Q6) -> 0 | G8: =if('Ciclo 5'!G3="",0,'Ciclo 1'!Q6) -> 0 | I8: Lucro teórico | J8: Lucro teórico %
B9: Lucro do Ciclo | C9: ='Ciclo 1'!Q7 -> 0 | D9: ='Ciclo 2'!Q7 -> 0 | E9: ='Ciclo 3'!Q7 -> 0 | F9: ='Ciclo 4'!Q7 -> 0 | G9: ='Ciclo 5'!Q7 -> 0 | I9: =SUM(C10:G10) -> 409.375 | J9: =I9/I3 -> 4.09375
B10: Saque Teórico | C10: =C7-D3 -> 50 | D10: 25 | E10: 50 | F10: 50 | G10: =G7 -> 234.375
B11: Saque Real | I11: Lucro Atual | J11: Lucro Final
I12: =SUM(C9:G9) -> 0 | J12: =I12/I3 -> 0
B13: Método de Ciclos - Nettuno
B16: Estratégia | C16: Entradas | D16: Valor | E16: %Médio | F16: %Total
C17: =countif('Ciclo 1'!M:M,$B17)+countif('Ciclo 2'!M:M,$B17)+countif('Ciclo 3'!M:M,$B17)+countif('Ciclo 4'!M:M,$B17)+countif('Ciclo 5'!M:M,$B17) -> 0 | D17: =sumif('Ciclo 1'!$M:$M,$B17,'Ciclo 1'!G:G)+sumif('Ciclo 2'!$M:$M,$B17,'Ciclo 2'!G:G)+sumif('Ciclo 3'!$M:$M,$B17,'Ciclo 3'!G:G)+sumif('Ciclo 4'!$M:$M,$B17,'Ciclo 4'!G:G)+sumif('Ciclo 5'!$M:$M,$B17,'Ciclo 5'!G:G) -> 0 | E17: =iferror((sumif('Ciclo 1'!M:M,#REF!,'Ciclo 1'!H:H)+sumif('Ciclo 2'!M:M,#REF!,'Ciclo 2'!H:H)+sumif('Ciclo 3'!M:M,#REF!,'Ciclo 3'!H:H)+sumif('Ciclo 4'!M:M,#REF!,'Ciclo 4'!H:H)+sumif('Ciclo 5'!M:M,#REF!,'Ciclo 5'!H:H))/C17,"") | F17: =IFERROR(D17/$D$35,"") | H17: O método deve ser aplicado em Exchange, para você poder utilizar o lay. Não é possivel fazer o Método de Ciclos em casas de apostas. Abaixo seguem as 2 melhores opções de exchanges.
C18: =countif('Ciclo 1'!M:M,$B18)+countif('Ciclo 2'!M:M,$B18)+countif('Ciclo 3'!M:M,$B18)+countif('Ciclo 4'!M:M,$B18)+countif('Ciclo 5'!M:M,$B18) -> 0 | D18: =sumif('Ciclo 1'!$M:$M,$B18,'Ciclo 1'!G:G)+sumif('Ciclo 2'!$M:$M,$B18,'Ciclo 2'!G:G)+sumif('Ciclo 3'!$M:$M,$B18,'Ciclo 3'!G:G)+sumif('Ciclo 4'!$M:$M,$B18,'Ciclo 4'!G:G)+sumif('Ciclo 5'!$M:$M,$B18,'Ciclo 5'!G:G) -> 0 | E18: =iferror((sumif('Ciclo 1'!M:M,#REF!,'Ciclo 1'!H:H)+sumif('Ciclo 2'!M:M,#REF!,'Ciclo 2'!H:H)+sumif('Ciclo 3'!M:M,#REF!,'Ciclo 3'!H:H)+sumif('Ciclo 4'!M:M,#REF!,'Ciclo 4'!H:H)+sumif('Ciclo 5'!M:M,#REF!,'Ciclo 5'!H:H))/C18,"") | F18: =IFERROR(D18/$D$35,"")
C19: =countif('Ciclo 1'!M:M,$B19)+countif('Ciclo 2'!M:M,$B19)+countif('Ciclo 3'!M:M,$B19)+countif('Ciclo 4'!M:M,$B19)+countif('Ciclo 5'!M:M,$B19) -> 0 | D19: =sumif('Ciclo 1'!$M:$M,$B19,'Ciclo 1'!G:G)+sumif('Ciclo 2'!$M:$M,$B19,'Ciclo 2'!G:G)+sumif('Ciclo 3'!$M:$M,$B19,'Ciclo 3'!G:G)+sumif('Ciclo 4'!$M:$M,$B19,'Ciclo 4'!G:G)+sumif('Ciclo 5'!$M:$M,$B19,'Ciclo 5'!G:G) -> 0 | E19: =iferror((sumif('Ciclo 1'!M:M,#REF!,'Ciclo 1'!H:H)+sumif('Ciclo 2'!M:M,#REF!,'Ciclo 2'!H:H)+sumif('Ciclo 3'!M:M,#REF!,'Ciclo 3'!H:H)+sumif('Ciclo 4'!M:M,#REF!,'Ciclo 4'!H:H)+sumif('Ciclo 5'!M:M,#REF!,'Ciclo 5'!H:H))/C19,"") | F19: =IFERROR(D19/$D$35,"")
C20: =countif('Ciclo 1'!M:M,$B20)+countif('Ciclo 2'!M:M,$B20)+countif('Ciclo 3'!M:M,$B20)+countif('Ciclo 4'!M:M,$B20)+countif('Ciclo 5'!M:M,$B20) -> 0 | D20: =sumif('Ciclo 1'!$M:$M,$B20,'Ciclo 1'!G:G)+sumif('Ciclo 2'!$M:$M,$B20,'Ciclo 2'!G:G)+sumif('Ciclo 3'!$M:$M,$B20,'Ciclo 3'!G:G)+sumif('Ciclo 4'!$M:$M,$B20,'Ciclo 4'!G:G)+sumif('Ciclo 5'!$M:$M,$B20,'Ciclo 5'!G:G) -> 0 | E20: =iferror((sumif('Ciclo 1'!M:M,#REF!,'Ciclo 1'!H:H)+sumif('Ciclo 2'!M:M,#REF!,'Ciclo 2'!H:H)+sumif('Ciclo 3'!M:M,#REF!,'Ciclo 3'!H:H)+sumif('Ciclo 4'!M:M,#REF!,'Ciclo 4'!H:H)+sumif('Ciclo 5'!M:M,#REF!,'Ciclo 5'!H:H))/C20,"") | F20: =IFERROR(D20/$D$35,"")
C21: =countif('Ciclo 1'!M:M,$B21)+countif('Ciclo 2'!M:M,$B21)+countif('Ciclo 3'!M:M,$B21)+countif('Ciclo 4'!M:M,$B21)+countif('Ciclo 5'!M:M,$B21) -> 0 | D21: =sumif('Ciclo 1'!$M:$M,$B21,'Ciclo 1'!G:G)+sumif('Ciclo 2'!$M:$M,$B21,'Ciclo 2'!G:G)+sumif('Ciclo 3'!$M:$M,$B21,'Ciclo 3'!G:G)+sumif('Ciclo 4'!$M:$M,$B21,'Ciclo 4'!G:G)+sumif('Ciclo 5'!$M:$M,$B21,'Ciclo 5'!G:G) -> 0 | E21: =iferror((sumif('Ciclo 1'!M:M,#REF!,'Ciclo 1'!H:H)+sumif('Ciclo 2'!M:M,#REF!,'Ciclo 2'!H:H)+sumif('Ciclo 3'!M:M,#REF!,'Ciclo 3'!H:H)+sumif('Ciclo 4'!M:M,#REF!,'Ciclo 4'!H:H)+sumif('Ciclo 5'!M:M,#REF!,'Ciclo 5'!H:H))/C21,"") | F21: =IFERROR(D21/$D$35,"")
C22: =countif('Ciclo 1'!M:M,$B22)+countif('Ciclo 2'!M:M,$B22)+countif('Ciclo 3'!M:M,$B22)+countif('Ciclo 4'!M:M,$B22)+countif('Ciclo 5'!M:M,$B22) -> 0 | D22: =sumif('Ciclo 1'!$M:$M,$B22,'Ciclo 1'!G:G)+sumif('Ciclo 2'!$M:$M,$B22,'Ciclo 2'!G:G)+sumif('Ciclo 3'!$M:$M,$B22,'Ciclo 3'!G:G)+sumif('Ciclo 4'!$M:$M,$B22,'Ciclo 4'!G:G)+sumif('Ciclo 5'!$M:$M,$B22,'Ciclo 5'!G:G) -> 0 | E22: =iferror((sumif('Ciclo 1'!M:M,#REF!,'Ciclo 1'!H:H)+sumif('Ciclo 2'!M:M,#REF!,'Ciclo 2'!H:H)+sumif('Ciclo 3'!M:M,#REF!,'Ciclo 3'!H:H)+sumif('Ciclo 4'!M:M,#REF!,'Ciclo 4'!H:H)+sumif('Ciclo 5'!M:M,#REF!,'Ciclo 5'!H:H))/C22,"") | F22: =IFERROR(D22/$D$35,"")
C23: =countif('Ciclo 1'!M:M,$B23)+countif('Ciclo 2'!M:M,$B23)+countif('Ciclo 3'!M:M,$B23)+countif('Ciclo 4'!M:M,$B23)+countif('Ciclo 5'!M:M,$B23) -> 0 | D23: =sumif('Ciclo 1'!$M:$M,$B23,'Ciclo 1'!G:G)+sumif('Ciclo 2'!$M:$M,$B23,'Ciclo 2'!G:G)+sumif('Ciclo 3'!$M:$M,$B23,'Ciclo 3'!G:G)+sumif('Ciclo 4'!$M:$M,$B23,'Ciclo 4'!G:G)+sumif('Ciclo 5'!$M:$M,$B23,'Ciclo 5'!G:G) -> 0 | E23: =iferror((sumif('Ciclo 1'!M:M,#REF!,'Ciclo 1'!H:H)+sumif('Ciclo 2'!M:M,#REF!,'Ciclo 2'!H:H)+sumif('Ciclo 3'!M:M,#REF!,'Ciclo 3'!H:H)+sumif('Ciclo 4'!M:M,#REF!,'Ciclo 4'!H:H)+sumif('Ciclo 5'!M:M,#REF!,'Ciclo 5'!H:H))/C23,"") | F23: =IFERROR(D23/$D$35,"")
C24: =countif('Ciclo 1'!M:M,$B24)+countif('Ciclo 2'!M:M,$B24)+countif('Ciclo 3'!M:M,$B24)+countif('Ciclo 4'!M:M,$B24)+countif('Ciclo 5'!M:M,$B24) -> 0 | D24: =sumif('Ciclo 1'!$M:$M,$B24,'Ciclo 1'!G:G)+sumif('Ciclo 2'!$M:$M,$B24,'Ciclo 2'!G:G)+sumif('Ciclo 3'!$M:$M,$B24,'Ciclo 3'!G:G)+sumif('Ciclo 4'!$M:$M,$B24,'Ciclo 4'!G:G)+sumif('Ciclo 5'!$M:$M,$B24,'Ciclo 5'!G:G) -> 0 | E24: =iferror((sumif('Ciclo 1'!M:M,#REF!,'Ciclo 1'!H:H)+sumif('Ciclo 2'!M:M,#REF!,'Ciclo 2'!H:H)+sumif('Ciclo 3'!M:M,#REF!,'Ciclo 3'!H:H)+sumif('Ciclo 4'!M:M,#REF!,'Ciclo 4'!H:H)+sumif('Ciclo 5'!M:M,#REF!,'Ciclo 5'!H:H))/C24,"") | F24: =IFERROR(D24/$D$35,"") | H24: Bolsa de Aposta, melhor custo benefício de exchange no mercado.
C25: =countif('Ciclo 1'!M:M,$B25)+countif('Ciclo 2'!M:M,$B25)+countif('Ciclo 3'!M:M,$B25)+countif('Ciclo 4'!M:M,$B25)+countif('Ciclo 5'!M:M,$B25) -> 0 | D25: =sumif('Ciclo 1'!$M:$M,$B25,'Ciclo 1'!G:G)+sumif('Ciclo 2'!$M:$M,$B25,'Ciclo 2'!G:G)+sumif('Ciclo 3'!$M:$M,$B25,'Ciclo 3'!G:G)+sumif('Ciclo 4'!$M:$M,$B25,'Ciclo 4'!G:G)+sumif('Ciclo 5'!$M:$M,$B25,'Ciclo 5'!G:G) -> 0 | E25: =iferror((sumif('Ciclo 1'!M:M,#REF!,'Ciclo 1'!H:H)+sumif('Ciclo 2'!M:M,#REF!,'Ciclo 2'!H:H)+sumif('Ciclo 3'!M:M,#REF!,'Ciclo 3'!H:H)+sumif('Ciclo 4'!M:M,#REF!,'Ciclo 4'!H:H)+sumif('Ciclo 5'!M:M,#REF!,'Ciclo 5'!H:H))/C25,"") | F25: =IFERROR(D25/$D$35,"")
C26: =countif('Ciclo 1'!M:M,$B26)+countif('Ciclo 2'!M:M,$B26)+countif('Ciclo 3'!M:M,$B26)+countif('Ciclo 4'!M:M,$B26)+countif('Ciclo 5'!M:M,$B26) -> 0 | D26: =sumif('Ciclo 1'!$M:$M,$B26,'Ciclo 1'!G:G)+sumif('Ciclo 2'!$M:$M,$B26,'Ciclo 2'!G:G)+sumif('Ciclo 3'!$M:$M,$B26,'Ciclo 3'!G:G)+sumif('Ciclo 4'!$M:$M,$B26,'Ciclo 4'!G:G)+sumif('Ciclo 5'!$M:$M,$B26,'Ciclo 5'!G:G) -> 0 | E26: =iferror((sumif('Ciclo 1'!M:M,#REF!,'Ciclo 1'!H:H)+sumif('Ciclo 2'!M:M,#REF!,'Ciclo 2'!H:H)+sumif('Ciclo 3'!M:M,#REF!,'Ciclo 3'!H:H)+sumif('Ciclo 4'!M:M,#REF!,'Ciclo 4'!H:H)+sumif('Ciclo 5'!M:M,#REF!,'Ciclo 5'!H:H))/C26,"") | F26: =IFERROR(D26/$D$35,"")
C27: =countif('Ciclo 1'!M:M,$B27)+countif('Ciclo 2'!M:M,$B27)+countif('Ciclo 3'!M:M,$B27)+countif('Ciclo 4'!M:M,$B27)+countif('Ciclo 5'!M:M,$B27) -> 0 | D27: =sumif('Ciclo 1'!$M:$M,$B27,'Ciclo 1'!G:G)+sumif('Ciclo 2'!$M:$M,$B27,'Ciclo 2'!G:G)+sumif('Ciclo 3'!$M:$M,$B27,'Ciclo 3'!G:G)+sumif('Ciclo 4'!$M:$M,$B27,'Ciclo 4'!G:G)+sumif('Ciclo 5'!$M:$M,$B27,'Ciclo 5'!G:G) -> 0 | E27: =iferror((sumif('Ciclo 1'!M:M,#REF!,'Ciclo 1'!H:H)+sumif('Ciclo 2'!M:M,#REF!,'Ciclo 2'!H:H)+sumif('Ciclo 3'!M:M,#REF!,'Ciclo 3'!H:H)+sumif('Ciclo 4'!M:M,#REF!,'Ciclo 4'!H:H)+sumif('Ciclo 5'!M:M,#REF!,'Ciclo 5'!H:H))/C27,"") | F27: =IFERROR(D27/$D$35,"")
C28: =countif('Ciclo 1'!M:M,$B28)+countif('Ciclo 2'!M:M,$B28)+countif('Ciclo 3'!M:M,$B28)+countif('Ciclo 4'!M:M,$B28)+countif('Ciclo 5'!M:M,$B28) -> 0 | D28: =sumif('Ciclo 1'!$M:$M,$B28,'Ciclo 1'!G:G)+sumif('Ciclo 2'!$M:$M,$B28,'Ciclo 2'!G:G)+sumif('Ciclo 3'!$M:$M,$B28,'Ciclo 3'!G:G)+sumif('Ciclo 4'!$M:$M,$B28,'Ciclo 4'!G:G)+sumif('Ciclo 5'!$M:$M,$B28,'Ciclo 5'!G:G) -> 0 | E28: =iferror((sumif('Ciclo 1'!M:M,#REF!,'Ciclo 1'!H:H)+sumif('Ciclo 2'!M:M,#REF!,'Ciclo 2'!H:H)+sumif('Ciclo 3'!M:M,#REF!,'Ciclo 3'!H:H)+sumif('Ciclo 4'!M:M,#REF!,'Ciclo 4'!H:H)+sumif('Ciclo 5'!M:M,#REF!,'Ciclo 5'!H:H))/C28,"") | F28: =IFERROR(D28/$D$35,"")
C29: =countif('Ciclo 1'!M:M,$B29)+countif('Ciclo 2'!M:M,$B29)+countif('Ciclo 3'!M:M,$B29)+countif('Ciclo 4'!M:M,$B29)+countif('Ciclo 5'!M:M,$B29) -> 0 | D29: =sumif('Ciclo 1'!$M:$M,$B29,'Ciclo 1'!G:G)+sumif('Ciclo 2'!$M:$M,$B29,'Ciclo 2'!G:G)+sumif('Ciclo 3'!$M:$M,$B29,'Ciclo 3'!G:G)+sumif('Ciclo 4'!$M:$M,$B29,'Ciclo 4'!G:G)+sumif('Ciclo 5'!$M:$M,$B29,'Ciclo 5'!G:G) -> 0 | E29: =iferror((sumif('Ciclo 1'!M:M,#REF!,'Ciclo 1'!H:H)+sumif('Ciclo 2'!M:M,#REF!,'Ciclo 2'!H:H)+sumif('Ciclo 3'!M:M,#REF!,'Ciclo 3'!H:H)+sumif('Ciclo 4'!M:M,#REF!,'Ciclo 4'!H:H)+sumif('Ciclo 5'!M:M,#REF!,'Ciclo 5'!H:H))/C29,"") | F29: =IFERROR(D29/$D$35,"")
C30: =countif('Ciclo 1'!M:M,$B30)+countif('Ciclo 2'!M:M,$B30)+countif('Ciclo 3'!M:M,$B30)+countif('Ciclo 4'!M:M,$B30)+countif('Ciclo 5'!M:M,$B30) -> 0 | D30: =sumif('Ciclo 1'!$M:$M,$B30,'Ciclo 1'!G:G)+sumif('Ciclo 2'!$M:$M,$B30,'Ciclo 2'!G:G)+sumif('Ciclo 3'!$M:$M,$B30,'Ciclo 3'!G:G)+sumif('Ciclo 4'!$M:$M,$B30,'Ciclo 4'!G:G)+sumif('Ciclo 5'!$M:$M,$B30,'Ciclo 5'!G:G) -> 0 | E30: =iferror((sumif('Ciclo 1'!M:M,#REF!,'Ciclo 1'!H:H)+sumif('Ciclo 2'!M:M,#REF!,'Ciclo 2'!H:H)+sumif('Ciclo 3'!M:M,#REF!,'Ciclo 3'!H:H)+sumif('Ciclo 4'!M:M,#REF!,'Ciclo 4'!H:H)+sumif('Ciclo 5'!M:M,#REF!,'Ciclo 5'!H:H))/C30,"") | F30: =IFERROR(D30/$D$35,"") | H30: Betfair, Bonûs de R$200 ao abrir a conta.
C31: =countif('Ciclo 1'!M:M,$B31)+countif('Ciclo 2'!M:M,$B31)+countif('Ciclo 3'!M:M,$B31)+countif('Ciclo 4'!M:M,$B31)+countif('Ciclo 5'!M:M,$B31) -> 0 | D31: =sumif('Ciclo 1'!$M:$M,$B31,'Ciclo 1'!G:G)+sumif('Ciclo 2'!$M:$M,$B31,'Ciclo 2'!G:G)+sumif('Ciclo 3'!$M:$M,$B31,'Ciclo 3'!G:G)+sumif('Ciclo 4'!$M:$M,$B31,'Ciclo 4'!G:G)+sumif('Ciclo 5'!$M:$M,$B31,'Ciclo 5'!G:G) -> 0 | E31: =iferror((sumif('Ciclo 1'!M:M,#REF!,'Ciclo 1'!H:H)+sumif('Ciclo 2'!M:M,#REF!,'Ciclo 2'!H:H)+sumif('Ciclo 3'!M:M,#REF!,'Ciclo 3'!H:H)+sumif('Ciclo 4'!M:M,#REF!,'Ciclo 4'!H:H)+sumif('Ciclo 5'!M:M,#REF!,'Ciclo 5'!H:H))/C31,"") | F31: =IFERROR(D31/$D$35,"")
C32: =countif('Ciclo 1'!M:M,$B32)+countif('Ciclo 2'!M:M,$B32)+countif('Ciclo 3'!M:M,$B32)+countif('Ciclo 4'!M:M,$B32)+countif('Ciclo 5'!M:M,$B32) -> 0 | D32: =sumif('Ciclo 1'!$M:$M,$B32,'Ciclo 1'!G:G)+sumif('Ciclo 2'!$M:$M,$B32,'Ciclo 2'!G:G)+sumif('Ciclo 3'!$M:$M,$B32,'Ciclo 3'!G:G)+sumif('Ciclo 4'!$M:$M,$B32,'Ciclo 4'!G:G)+sumif('Ciclo 5'!$M:$M,$B32,'Ciclo 5'!G:G) -> 0 | E32: =iferror((sumif('Ciclo 1'!M:M,#REF!,'Ciclo 1'!H:H)+sumif('Ciclo 2'!M:M,#REF!,'Ciclo 2'!H:H)+sumif('Ciclo 3'!M:M,#REF!,'Ciclo 3'!H:H)+sumif('Ciclo 4'!M:M,#REF!,'Ciclo 4'!H:H)+sumif('Ciclo 5'!M:M,#REF!,'Ciclo 5'!H:H))/C32,"") | F32: =IFERROR(D32/$D$35,"")
C33: =countif('Ciclo 1'!M:M,$B33)+countif('Ciclo 2'!M:M,$B33)+countif('Ciclo 3'!M:M,$B33)+countif('Ciclo 4'!M:M,$B33)+countif('Ciclo 5'!M:M,$B33) -> 0 | D33: =sumif('Ciclo 1'!$M:$M,$B33,'Ciclo 1'!G:G)+sumif('Ciclo 2'!$M:$M,$B33,'Ciclo 2'!G:G)+sumif('Ciclo 3'!$M:$M,$B33,'Ciclo 3'!G:G)+sumif('Ciclo 4'!$M:$M,$B33,'Ciclo 4'!G:G)+sumif('Ciclo 5'!$M:$M,$B33,'Ciclo 5'!G:G) -> 0 | E33: =iferror((sumif('Ciclo 1'!M:M,#REF!,'Ciclo 1'!H:H)+sumif('Ciclo 2'!M:M,#REF!,'Ciclo 2'!H:H)+sumif('Ciclo 3'!M:M,#REF!,'Ciclo 3'!H:H)+sumif('Ciclo 4'!M:M,#REF!,'Ciclo 4'!H:H)+sumif('Ciclo 5'!M:M,#REF!,'Ciclo 5'!H:H))/C33,"") | F33: =IFERROR(D33/$D$35,"")
B35: Totais | C35: =sum(C17:C33) -> 0 | D35: =sum(D17:D33) -> 0 | E35: =IFERROR(average('Ciclo 1'!H3:H81,'Ciclo 2'!H3:H81,'Ciclo 3'!H3:H81,'Ciclo 4'!H3:H81,'Ciclo 5'!H3:H81),"")
H36: Aplique o Método de Ciclos de maneira eficiente
B37: Campeonato | C37: Entradas | D37: Valor | E37: %Médio | F37: %Total
B38: =if(Apoio!V1="",,Apoio!V1) | C38: =if(Apoio!W1="",,Apoio!W1) | D38: =if(Apoio!X1="",,Apoio!X1) | E38: =if(Apoio!Y1="",,Apoio!Y1) | F38: =if(Apoio!Z1="",,Apoio!Z1)
B39: =if(Apoio!V2="",,Apoio!V2) | C39: =if(Apoio!W2="",,Apoio!W2) | D39: =if(Apoio!X2="",,Apoio!X2) | E39: =if(Apoio!Y2="",,Apoio!Y2) | F39: =if(Apoio!Z2="",,Apoio!Z2)
B40: =if(Apoio!V3="",,Apoio!V3) | C40: =if(Apoio!W3="",,Apoio!W3) | D40: =if(Apoio!X3="",,Apoio!X3) | E40: =if(Apoio!Y3="",,Apoio!Y3) | F40: =if(Apoio!Z3="",,Apoio!Z3)
B41: =if(Apoio!V4="",,Apoio!V4) | C41: =if(Apoio!W4="",,Apoio!W4) | D41: =if(Apoio!X4="",,Apoio!X4) | E41: =if(Apoio!Y4="",,Apoio!Y4) | F41: =if(Apoio!Z4="",,Apoio!Z4)
B42: =if(Apoio!V5="",,Apoio!V5) | C42: =if(Apoio!W5="",,Apoio!W5) | D42: =if(Apoio!X5="",,Apoio!X5) | E42: =if(Apoio!Y5="",,Apoio!Y5) | F42: =if(Apoio!Z5="",,Apoio!Z5)
B43: =if(Apoio!V6="",,Apoio!V6) | C43: =if(Apoio!W6="",,Apoio!W6) | D43: =if(Apoio!X6="",,Apoio!X6) | E43: =if(Apoio!Y6="",,Apoio!Y6) | F43: =if(Apoio!Z6="",,Apoio!Z6)
B44: =if(Apoio!V7="",,Apoio!V7) | C44: =if(Apoio!W7="",,Apoio!W7) | D44: =if(Apoio!X7="",,Apoio!X7) | E44: =if(Apoio!Y7="",,Apoio!Y7) | F44: =if(Apoio!Z7="",,Apoio!Z7)
...

Sheet Ciclo 1
A1: =IF(Diretrizes!J3<2,"",Diretrizes!J3) -> 12 | C1: Banca | D1: Banca | E1: Obj/Banca | F1: Obj./Banca
B2: Jogo | C2: Trabalho | D2: Teórica | E2: Trabalho | F2: Teórica | G2: Lucro | H2: %S.B. Trab | I2: Resíduo | J2: Objetivo | L2: Jogo | M2: Estratégia | N2: Campeonato | P2: Início
B3: 1 | C3: =Diretrizes!C3 -> 100 | D3: =C3 -> 100 | E3: =IF(C3="",,IF(B3="",,C3*J3)) -> 4 | F3: =if(D3="",,D3*J3) -> 4 | H3: =IF(G3="",,G3/C3) | I3: =if(G3="",,G3-F3) | J3: =Diretrizes!C4 -> 0.04 | P3: Fim | V3: =if(L3="","", left(L3, find(" x ",L3)-1)) | W3: =if(L3="","", TRIM(mid(L3,find(" x ",L3)+3,20)))
B4: =IF(B3<$A$1,B3+1,if($A$1="",B3+1,"")) -> 2 | C4: =IF(G3<>0,C3+G3,) | D4: =if(C4="",,D3*(1+J3)) | E4: =IF(C4="",,IF(B4="",,C4*J4)) | F4: =if(D4="",,D4*J4) | H4: =IF(G4="",,G4/C4) | I4: =if(G4="",,G4-F4) | J4: =if(B4<>"",J3*(1-Diretrizes!C$5),) -> 0.04 | K4: =IF(AND(D4>$Q$10,D3<$Q$10),"OK","NOK") -> NOK | V4: =if(L4="","", left(L4, find(" x ",L4)-1)) | W4: =if(L4="","", TRIM(mid(L4,find(" x ",L4)+3,20)))
B5: =IF(B4<$A$1,B4+1,if($A$1="",B4+1,"")) -> 3 | C5: =IF(G4<>0,C4+G4,) | D5: =if(C5="",,D4*(1+J4)) | E5: =IF(C5="",,IF(B5="",,C5*J5)) | F5: =if(D5="",,D5*J5) | H5: =IF(G5="",,G5/C5) | I5: =if(G5="",,G5-F5) | J5: =if(B5<>"",J4*(1-Diretrizes!C$5),) -> 0.04 | K5: =IF(AND(D5>$Q$10,D4<$Q$10),"OK","NOK") -> NOK | P5: Banca Inicial | Q5: =Diretrizes!C3 -> 100 | S5: Resíduo | T5: =SUM(I3:I32) -> 0 | V5: =if(L5="","", left(L5, find(" x ",L5)-1)) | W5: =if(L5="","", TRIM(mid(L5,find(" x ",L5)+3,20)))
B6: =IF(B5<$A$1,B5+1,if($A$1="",B5+1,"")) -> 4 | C6: =IF(G5<>0,C5+G5,) | D6: =if(C6="",,D5*(1+J5)) | E6: =IF(C6="",,IF(B6="",,C6*J6)) | F6: =if(D6="",,D6*J6) | H6: =IF(G6="",,G6/C6) | I6: =if(G6="",,G6-F6) | J6: =if(B6<>"",J5*(1-Diretrizes!C$5),) -> 0.04 | K6: =IF(AND(D6>$Q$10,D5<$Q$10),"OK","NOK") -> NOK | P6: Banca Atual | Q6: =Q7+C3 -> 100 | V6: =if(L6="","", left(L6, find(" x ",L6)-1)) | W6: =if(L6="","", TRIM(mid(L6,find(" x ",L6)+3,20)))
B7: =IF(B6<$A$1,B6+1,if($A$1="",B6+1,"")) -> 5 | C7: =IF(G6<>0,C6+G6,) | D7: =if(C7="",,D6*(1+J6)) | E7: =IF(C7="",,IF(B7="",,C7*J7)) | F7: =if(D7="",,D7*J7) | H7: =IF(G7="",,G7/C7) | I7: =if(G7="",,G7-F7) | J7: =if(B7<>"",J6*(1-Diretrizes!C$5),) -> 0.04 | K7: =IF(AND(D7>$Q$10,D6<$Q$10),"OK","NOK") -> NOK | P7: Lucro do ciclo | Q7: =SUM(G3:G32) -> 0 | S7: Saque | T7: =IF(G3="",,Q6-'Ciclo 2'!Q5) | V7: =if(L7="","", left(L7, find(" x ",L7)-1)) | W7: =if(L7="","", TRIM(mid(L7,find(" x ",L7)+3,20)))
B8: =IF(B7<$A$1,B7+1,if($A$1="",B7+1,"")) -> 6 | C8: =IF(G7<>0,C7+G7,) | D8: =if(C8="",,D7*(1+J7)) | E8: =IF(C8="",,IF(B8="",,C8*J8)) | F8: =if(D8="",,D8*J8) | H8: =IF(G8="",,G8/C8) | I8: =if(G8="",,G8-F8) | J8: =if(B8<>"",J7*(1-Diretrizes!C$5),) -> 0.04 | K8: =IF(AND(D8>$Q$10,D7<$Q$10),"OK","NOK") -> NOK | P8: Lucro % | Q8: =Q6/C3-1 -> 0 | V8: =if(L8="","", left(L8, find(" x ",L8)-1)) | W8: =if(L8="","", TRIM(mid(L8,find(" x ",L8)+3,20)))
B9: =IF(B8<$A$1,B8+1,if($A$1="",B8+1,"")) -> 7 | C9: =IF(G8<>0,C8+G8,) | D9: =if(C9="",,D8*(1+J8)) | E9: =IF(C9="",,IF(B9="",,C9*J9)) | F9: =if(D9="",,D9*J9) | H9: =IF(G9="",,G9/C9) | I9: =if(G9="",,G9-F9) | J9: =if(B9<>"",J8*(1-Diretrizes!C$5),) -> 0.04 | K9: =IF(AND(D9>$Q$10,D8<$Q$10),"OK","NOK") -> NOK | V9: =if(L9="","", left(L9, find(" x ",L9)-1)) | W9: =if(L9="","", TRIM(mid(L9,find(" x ",L9)+3,20)))
B10: =IF(B9<$A$1,B9+1,if($A$1="",B9+1,"")) -> 8 | C10: =IF(G9<>0,C9+G9,) | D10: =if(C10="",,D9*(1+J9)) | E10: =IF(C10="",,IF(B10="",,C10*J10)) | F10: =if(D10="",,D10*J10) | H10: =IF(G10="",,G10/C10) | I10: =if(G10="",,G10-F10) | J10: =if(B10<>"",J9*(1-Diretrizes!C$5),) -> 0.04 | K10: =IF(AND(D10>$Q$10,D9<$Q$10),"OK","NOK") -> NOK | P10: Parar com | Q10: =Diretrizes!C7 -> 150 | V10: =if(L10="","", left(L10, find(" x ",L10)-1)) | W10: =if(L10="","", TRIM(mid(L10,find(" x ",L10)+3,20)))
B11: =IF(B10<$A$1,B10+1,if($A$1="",B10+1,"")) -> 9 | C11: =IF(G10<>0,C10+G10,) | D11: =if(C11="",,D10*(1+J10)) | E11: =IF(C11="",,IF(B11="",,C11*J11)) | F11: =if(D11="",,D11*J11) | H11: =IF(G11="",,G11/C11) | I11: =if(G11="",,G11-F11) | J11: =if(B11<>"",J10*(1-Diretrizes!C$5),) -> 0.04 | K11: =IF(AND(D11>$Q$10,D10<$Q$10),"OK","NOK") -> NOK | V11: =if(L11="","", left(L11, find(" x ",L11)-1)) | W11: =if(L11="","", TRIM(mid(L11,find(" x ",L11)+3,20)))
B12: =IF(B11<$A$1,B11+1,if($A$1="",B11+1,"")) -> 10 | C12: =IF(G11<>0,C11+G11,) | D12: =if(C12="",,D11*(1+J11)) | E12: =IF(C12="",,IF(B12="",,C12*J12)) | F12: =if(D12="",,D12*J12) | H12: =IF(G12="",,G12/C12) | I12: =if(G12="",,G12-F12) | J12: =if(B12<>"",J11*(1-Diretrizes!C$5),) -> 0.04 | K12: =IF(AND(D12>$Q$10,D11<$Q$10),"OK","NOK") -> NOK | P12: Desempenho por Estratégia | V12: =if(L12="","", left(L12, find(" x ",L12)-1)) | W12: =if(L12="","", TRIM(mid(L12,find(" x ",L12)+3,20)))
B13: =IF(B12<$A$1,B12+1,if($A$1="",B12+1,"")) -> 11 | C13: =IF(G12<>0,C12+G12,) | D13: =if(C13="",,D12*(1+J12)) | E13: =IF(C13="",,IF(B13="",,C13*J13)) | F13: =if(D13="",,D13*J13) | H13: =IF(G13="",,G13/C13) | I13: =if(G13="",,G13-F13) | J13: =if(B13<>"",J12*(1-Diretrizes!C$5),) -> 0.04 | P13: Estratégia | Q13: Valor | R13: Qt | S13: %Médio | T13: %Total | V13: =if(L13="","", left(L13, find(" x ",L13)-1)) | W13: =if(L13="","", TRIM(mid(L13,find(" x ",L13)+3,20)))
B14: =IF(B13<$A$1,B13+1,if($A$1="",B13+1,"")) -> 12 | C14: =IF(G13<>0,C13+G13,) | D14: =if(C14="",,D13*(1+J13)) | E14: =IF(C14="",,IF(B14="",,C14*J14)) | F14: =if(D14="",,D14*J14) | H14: =IF(G14="",,G14/C14) | I14: =if(G14="",,G14-F14) | J14: =if(B14<>"",J13*(1-Diretrizes!C$5),) -> 0.04 | P14: {=sort(unique(M3:M112))} | Q14: =if(P14="","", sumif(M$3:M112,P14,G$3:G112)) | R14: =if(P14="","", countif(M$3:M112,P14)) | S14: =if(P14="","", averageif(M$3:M112,P14,H$3:H112)) | T14: =if(P14="","",Q14/sum($G$3:$G112)) | V14: =if(L14="","", left(L14, find(" x ",L14)-1)) | W14: =if(L14="","", TRIM(mid(L14,find(" x ",L14)+3,20)))
B15: =IF(B14<$A$1,B14+1,if($A$1="",B14+1,"")) | C15: =IF(G14<>0,C14+G14,) | D15: =if(C15="",,D14*(1+J14)) | E15: =IF(C15="",,IF(B15="",,C15*J15)) | F15: =if(D15="",,D15*J15) | H15: =IF(G15="",,G15/C15) | I15: =if(G15="",,G15-F15) | J15: =if(B15<>"",J14*(1-Diretrizes!C$5),) | Q15: =if(P15="","", sumif(M$3:M113,P15,G$3:G113)) | R15: =if(P15="","", countif(M$3:M113,P15)) | S15: =if(P15="","", averageif(M$3:M113,P15,H$3:H113)) | T15: =if(P15="","",Q15/sum($G$3:$G113)) | V15: =if(L15="","", left(L15, find(" x ",L15)-1)) | W15: =if(L15="","", TRIM(mid(L15,find(" x ",L15)+3,20)))
B16: =IF(B15<$A$1,B15+1,if($A$1="",B15+1,"")) | C16: =IF(G15<>0,C15+G15,) | D16: =if(C16="",,D15*(1+J15)) | E16: =IF(C16="",,IF(B16="",,C16*J16)) | F16: =if(D16="",,D16*J16) | H16: =IF(G16="",,G16/C16) | I16: =if(G16="",,G16-F16) | J16: =if(B16<>"",J15*(1-Diretrizes!C$5),) | Q16: =if(P16="","", sumif(M$3:M114,P16,G$3:G114)) | R16: =if(P16="","", countif(M$3:M114,P16)) | S16: =if(P16="","", averageif(M$3:M114,P16,H$3:H114)) | T16: =if(P16="","",Q16/sum($G$3:$G114)) | V16: =if(L16="","", left(L16, find(" x ",L16)-1)) | W16: =if(L16="","", TRIM(mid(L16,find(" x ",L16)+3,20)))
B17: =IF(B16<$A$1,B16+1,if($A$1="",B16+1,"")) | C17: =IF(G16<>0,C16+G16,) | D17: =if(C17="",,D16*(1+J16)) | E17: =IF(C17="",,IF(B17="",,C17*J17)) | F17: =if(D17="",,D17*J17) | H17: =IF(G17="",,G17/C17) | I17: =if(G17="",,G17-F17) | J17: =if(B17<>"",J16*(1-Diretrizes!C$5),) | Q17: =if(P17="","", sumif(M$3:M115,P17,G$3:G115)) | R17: =if(P17="","", countif(M$3:M115,P17)) | S17: =if(P17="","", averageif(M$3:M115,P17,H$3:H115)) | T17: =if(P17="","",Q17/sum($G$3:$G115)) | V17: =if(L17="","", left(L17, find(" x ",L17)-1)) | W17: =if(L17="","", TRIM(mid(L17,find(" x ",L17)+3,20)))
B18: =IF(B17<$A$1,B17+1,if($A$1="",B17+1,"")) | C18: =IF(G17<>0,C17+G17,) | D18: =if(C18="",,D17*(1+J17)) | E18: =IF(C18="",,IF(B18="",,C18*J18)) | F18: =if(D18="",,D18*J18) | H18: =IF(G18="",,G18/C18) | I18: =if(G18="",,G18-F18) | J18: =if(B18<>"",J17*(1-Diretrizes!C$5),) | Q18: =if(P18="","", sumif(M$3:M116,P18,G$3:G116)) | R18: =if(P18="","", countif(M$3:M116,P18)) | S18: =if(P18="","", averageif(M$3:M116,P18,H$3:H116)) | T18: =if(P18="","",Q18/sum($G$3:$G116)) | V18: =if(L18="","", left(L18, find(" x ",L18)-1)) | W18: =if(L18="","", TRIM(mid(L18,find(" x ",L18)+3,20)))
B19: =IF(B18<$A$1,B18+1,if($A$1="",B18+1,"")) | C19: =IF(G18<>0,C18+G18,) | D19: =if(C19="",,D18*(1+J18)) | E19: =IF(C19="",,IF(B19="",,C19*J19)) | F19: =if(D19="",,D19*J19) | H19: =IF(G19="",,G19/C19) | I19: =if(G19="",,G19-F19) | J19: =if(B19<>"",J18*(1-Diretrizes!C$5),) | Q19: =if(P19="","", sumif(M$3:M117,P19,G$3:G117)) | R19: =if(P19="","", countif(M$3:M117,P19)) | S19: =if(P19="","", averageif(M$3:M117,P19,H$3:H117)) | T19: =if(P19="","",Q19/sum($G$3:$G117)) | V19: =if(L19="","", left(L19, find(" x ",L19)-1)) | W19: =if(L19="","", TRIM(mid(L19,find(" x ",L19)+3,20)))
B20: =IF(B19<$A$1,B19+1,if($A$1="",B19+1,"")) | C20: =IF(G19<>0,C19+G19,) | D20: =if(C20="",,D19*(1+J19)) | E20: =IF(C20="",,IF(B20="",,C20*J20)) | F20: =if(D20="",,D20*J20) | H20: =IF(G20="",,G20/C20) | I20: =if(G20="",,G20-F20) | J20: =if(B20<>"",J19*(1-Diretrizes!C$5),) | Q20: =if(P20="","", sumif(M$3:M118,P20,G$3:G118)) | R20: =if(P20="","", countif(M$3:M118,P20)) | S20: =if(P20="","", averageif(M$3:M118,P20,H$3:H118)) | T20: =if(P20="","",Q20/sum($G$3:$G118)) | V20: =if(L20="","", left(L20, find(" x ",L20)-1)) | W20: =if(L20="","", TRIM(mid(L20,find(" x ",L20)+3,20)))
B21: =IF(B20<$A$1,B20+1,if($A$1="",B20+1,"")) | C21: =IF(G20<>0,C20+G20,) | D21: =if(C21="",,D20*(1+J20)) | E21: =IF(C21="",,IF(B21="",,C21*J21)) | F21: =if(D21="",,D21*J21) | H21: =IF(G21="",,G21/C21) | I21: =if(G21="",,G21-F21) | J21: =if(B21<>"",J20*(1-Diretrizes!C$5),) | Q21: =if(P21="","", sumif(M$3:M119,P21,G$3:G119)) | R21: =if(P21="","", countif(M$3:M119,P21)) | S21: =if(P21="","", averageif(M$3:M119,P21,H$3:H119)) | T21: =if(P21="","",Q21/sum($G$3:$G119)) | V21: =if(L21="","", left(L21, find(" x ",L21)-1)) | W21: =if(L21="","", TRIM(mid(L21,find(" x ",L21)+3,20)))
B22: =IF(B21<$A$1,B21+1,if($A$1="",B21+1,"")) | C22: =IF(G21<>0,C21+G21,) | D22: =if(C22="",,D21*(1+J21)) | E22: =IF(C22="",,IF(B22="",,C22*J22)) | F22: =if(D22="",,D22*J22) | H22: =IF(G22="",,G22/C22) | I22: =if(G22="",,G22-F22) | J22: =if(B22<>"",J21*(1-Diretrizes!C$5),) | Q22: =if(P22="","", sumif(M$3:M120,P22,G$3:G120)) | R22: =if(P22="","", countif(M$3:M120,P22)) | S22: =if(P22="","", averageif(M$3:M120,P22,H$3:H120)) | T22: =if(P22="","",Q22/sum($G$3:$G120)) | V22: =if(L22="","", left(L22, find(" x ",L22)-1)) | W22: =if(L22="","", TRIM(mid(L22,find(" x ",L22)+3,20)))
B23: =IF(B22<$A$1,B22+1,if($A$1="",B22+1,"")) | C23: =IF(G22<>0,C22+G22,) | D23: =if(C23="",,D22*(1+J22)) | E23: =IF(C23="",,IF(B23="",,C23*J23)) | F23: =if(D23="",,D23*J23) | H23: =IF(G23="",,G23/C23) | I23: =if(G23="",,G23-F23) | J23: =if(B23<>"",J22*(1-Diretrizes!C$5),) | Q23: =if(P23="","", sumif(M$3:M121,P23,G$3:G121)) | R23: =if(P23="","", countif(M$3:M121,P23)) | S23: =if(P23="","", averageif(M$3:M121,P23,H$3:H121)) | T23: =if(P23="","",Q23/sum($G$3:$G121)) | V23: =if(L23="","", left(L23, find(" x ",L23)-1)) | W23: =if(L23="","", TRIM(mid(L23,find(" x ",L23)+3,20)))
B24: =IF(B23<$A$1,B23+1,if($A$1="",B23+1,"")) | C24: =IF(G23<>0,C23+G23,) | D24: =if(C24="",,D23*(1+J23)) | E24: =IF(C24="",,IF(B24="",,C24*J24)) | F24: =if(D24="",,D24*J24) | H24: =IF(G24="",,G24/C24) | I24: =if(G24="",,G24-F24) | J24: =if(B24<>"",J23*(1-Diretrizes!C$5),) | Q24: =if(P24="","", sumif(M$3:M122,P24,G$3:G122)) | R24: =if(P24="","", countif(M$3:M122,P24)) | S24: =if(P24="","", averageif(M$3:M122,P24,H$3:H122)) | T24: =if(P24="","",Q24/sum($G$3:$G122)) | V24: =if(L24="","", left(L24, find(" x ",L24)-1)) | W24: =if(L24="","", TRIM(mid(L24,find(" x ",L24)+3,20)))
B25: =IF(B24<$A$1,B24+1,if($A$1="",B24+1,"")) | C25: =IF(G24<>0,C24+G24,) | D25: =if(C25="",,D24*(1+J24)) | E25: =IF(C25="",,IF(B25="",,C25*J25)) | F25: =if(D25="",,D25*J25) | H25: =IF(G25="",,G25/C25) | I25: =if(G25="",,G25-F25) | J25: =if(B25<>"",J24*(1-Diretrizes!C$5),) | P25: Desempenho por Campeonato | V25: =if(L25="","", left(L25, find(" x ",L25)-1)) | W25: =if(L25="","", TRIM(mid(L25,find(" x ",L25)+3,20)))
B26: =IF(B25<$A$1,B25+1,if($A$1="",B25+1,"")) | C26: =IF(G25<>0,C25+G25,) | D26: =if(C26="",,D25*(1+J25)) | E26: =IF(C26="",,IF(B26="",,C26*J26)) | F26: =if(D26="",,D26*J26) | H26: =IF(G26="",,G26/C26) | I26: =if(G26="",,G26-F26) | J26: =if(B26<>"",J25*(1-Diretrizes!C$5),) | P26: Estratégia | Q26: Valor | R26: Qt | S26: %Médio | T26: %Total | V26: =if(L26="","", left(L26, find(" x ",L26)-1)) | W26: =if(L26="","", TRIM(mid(L26,find(" x ",L26)+3,20)))
B27: =IF(B26<$A$1,B26+1,if($A$1="",B26+1,"")) | C27: =IF(G26<>0,C26+G26,) | D27: =if(C27="",,D26*(1+J26)) | E27: =IF(C27="",,IF(B27="",,C27*J27)) | F27: =if(D27="",,D27*J27) | H27: =IF(G27="",,G27/C27) | I27: =if(G27="",,G27-F27) | J27: =if(B27<>"",J26*(1-Diretrizes!C$5),) | P27: {=sort(unique(N3:N112))} | Q27: =if(P27="","", sumif(N$3:N112,P27,G$3:G112)) | R27: =if(P27="","", countif(N$3:N112,P27)) | S27: =if(P27="","", averageif(N$3:N112,P27,H$3:H112)) | T27: =IF(P27="","",Q27/SUM($G$3:$G112)) | V27: =if(L27="","", left(L27, find(" x ",L27)-1)) | W27: =if(L27="","", TRIM(mid(L27,find(" x ",L27)+3,20)))
B28: =IF(B27<$A$1,B27+1,if($A$1="",B27+1,"")) | C28: =IF(G27<>0,C27+G27,) | D28: =if(C28="",,D27*(1+J27)) | E28: =IF(C28="",,IF(B28="",,C28*J28)) | F28: =if(D28="",,D28*J28) | H28: =IF(G28="",,G28/C28) | I28: =if(G28="",,G28-F28) | J28: =if(B28<>"",J27*(1-Diretrizes!C$5),) | Q28: =if(P28="","", sumif(N$3:N113,P28,G$3:G113)) | R28: =if(P28="","", countif(N$3:N113,P28)) | S28: =if(P28="","", averageif(N$3:N113,P28,H$3:H113)) | T28: =IF(P28="","",Q28/SUM($G$3:$G113)) | V28: =if(L28="","", left(L28, find(" x ",L28)-1)) | W28: =if(L28="","", TRIM(mid(L28,find(" x ",L28)+3,20)))
B29: =IF(B28<$A$1,B28+1,if($A$1="",B28+1,"")) | C29: =IF(G28<>0,C28+G28,) | D29: =if(C29="",,D28*(1+J28)) | E29: =IF(C29="",,IF(B29="",,C29*J29)) | F29: =if(D29="",,D29*J29) | H29: =IF(G29="",,G29/C29) | I29: =if(G29="",,G29-F29) | J29: =if(B29<>"",J28*(1-Diretrizes!C$5),) | Q29: =if(P29="","", sumif(N$3:N114,P29,G$3:G114)) | R29: =if(P29="","", countif(N$3:N114,P29)) | S29: =if(P29="","", averageif(N$3:N114,P29,H$3:H114)) | T29: =IF(P29="","",Q29/SUM($G$3:$G114)) | V29: =if(L29="","", left(L29, find(" x ",L29)-1)) | W29: =if(L29="","", TRIM(mid(L29,find(" x ",L29)+3,20)))
B30: =IF(B29<$A$1,B29+1,if($A$1="",B29+1,"")) | C30: =IF(G29<>0,C29+G29,) | D30: =if(C30="",,D29*(1+J29)) | E30: =IF(C30="",,IF(B30="",,C30*J30)) | F30: =if(D30="",,D30*J30) | H30: =IF(G30="",,G30/C30) | I30: =if(G30="",,G30-F30) | J30: =if(B30<>"",J29*(1-Diretrizes!C$5),) | Q30: =if(P30="","", sumif(N$3:N115,P30,G$3:G115)) | R30: =if(P30="","", countif(N$3:N115,P30)) | S30: =if(P30="","", averageif(N$3:N115,P30,H$3:H115)) | T30: =IF(P30="","",Q30/SUM($G$3:$G115)) | V30: =if(L30="","", left(L30, find(" x ",L30)-1)) | W30: =if(L30="","", TRIM(mid(L30,find(" x ",L30)+3,20)))
B31: =IF(B30<$A$1,B30+1,if($A$1="",B30+1,"")) | C31: =IF(G30<>0,C30+G30,) | D31: =if(C31="",,D30*(1+J30)) | E31: =IF(C31="",,IF(B31="",,C31*J31)) | F31: =if(D31="",,D31*J31) | H31: =IF(G31="",,G31/C31) | I31: =if(G31="",,G31-F31) | J31: =if(B31<>"",J30*(1-Diretrizes!C$5),) | Q31: =if(P31="","", sumif(N$3:N116,P31,G$3:G116)) | R31: =if(P31="","", countif(N$3:N116,P31)) | S31: =if(P31="","", averageif(N$3:N116,P31,H$3:H116)) | T31: =IF(P31="","",Q31/SUM($G$3:$G116)) | V31: =if(L31="","", left(L31, find(" x ",L31)-1)) | W31: =if(L31="","", TRIM(mid(L31,find(" x ",L31)+3,20)))
B32: =IF(B31<$A$1,B31+1,if($A$1="",B31+1,"")) | C32: =IF(G31<>0,C31+G31,) | D32: =if(C32="",,D31*(1+J31)) | E32: =IF(C32="",,IF(B32="",,C32*J32)) | F32: =if(D32="",,D32*J32) | H32: =IF(G32="",,G32/C32) | I32: =if(G32="",,G32-F32) | J32: =if(B32<>"",J31*(1-Diretrizes!C$5),) | Q32: =if(P32="","", sumif(N$3:N117,P32,G$3:G117)) | R32: =if(P32="","", countif(N$3:N117,P32)) | S32: =if(P32="","", averageif(N$3:N117,P32,H$3:H117)) | T32: =IF(P32="","",Q32/SUM($G$3:$G117)) | V32: =if(L32="","", left(L32, find(" x ",L32)-1)) | W32: =if(L32="","", TRIM(mid(L32,find(" x ",L32)+3,20)))
C33: =IF(G32<>0,C32+G32,) | F33: =if(D33="",,D33*J33) | Q33: =if(P33="","", sumif(N$3:N118,P33,G$3:G118)) | R33: =if(P33="","", countif(N$3:N118,P33)) | S33: =if(P33="","", averageif(N$3:N118,P33,H$3:H118)) | T33: =IF(P33="","",Q33/SUM($G$3:$G118)) | V33: =if(L33="","", left(L33, find(" x ",L33)-1)) | W33: =if(L33="","", TRIM(mid(L33,find(" x ",L33)+3,20)))
Q34: =if(P34="","", sumif(N$3:N119,P34,G$3:G119)) | R34: =if(P34="","", countif(N$3:N119,P34)) | S34: =if(P34="","", averageif(N$3:N119,P34,H$3:H119)) | T34: =IF(P34="","",Q34/SUM($G$3:$G119)) | V34: =if(L34="","", left(L34, find(" x ",L34)-1)) | W34: =if(L34="","", TRIM(mid(L34,find(" x ",L34)+3,20)))
Q35: =if(P35="","", sumif(N$3:N120,P35,G$3:G120)) | R35: =if(P35="","", countif(N$3:N120,P35)) | S35: =if(P35="","", averageif(N$3:N120,P35,H$3:H120)) | T35: =IF(P35="","",Q35/SUM($G$3:$G120)) | V35: =if(L35="","", left(L35, find(" x ",L35)-1)) | W35: =if(L35="","", TRIM(mid(L35,find(" x ",L35)+3,20)))
Q36: =if(P36="","", sumif(N$3:N121,P36,G$3:G121)) | R36: =if(P36="","", countif(N$3:N121,P36)) | S36: =if(P36="","", averageif(N$3:N121,P36,H$3:H121)) | T36: =IF(P36="","",Q36/SUM($G$3:$G121)) | V36: =if(L36="","", left(L36, find(" x ",L36)-1)) | W36: =if(L36="","", TRIM(mid(L36,find(" x ",L36)+3,20)))
T37: =IF(P37="","",Q37/SUM($G$3:$G122)) | V37: =if(L37="","", left(L37, find(" x ",L37)-1)) | W37: =if(L37="","", TRIM(mid(L37,find(" x ",L37)+3,20)))
P38: Desempenho por Clube | V38: =if(L38="","", left(L38, find(" x ",L38)-1)) | W38: =if(L38="","", TRIM(mid(L38,find(" x ",L38)+3,20)))
P39: Clube | Q39: Valor | R39: Qt | S39: %Médio | T39: %Total | V39: =if(L39="","", left(L39, find(" x ",L39)-1)) | W39: =if(L39="","", TRIM(mid(L39,find(" x ",L39)+3,20)))
P40: {=sort(UNIQUE({V3:V112;W3:W112}))} | V40: =if(L40="","", left(L40, find(" x ",L40)-1)) | W40: =if(L40="","", TRIM(mid(L40,find(" x ",L40)+3,20)))
...

Sheet Ciclo 2
A1: =IF(Diretrizes!J3<2,"",Diretrizes!J3) -> 12 | C1: Banca | D1: Banca | E1: Obj/Banca | F1: Obj./Banca
B2: Jogo | C2: Trabalho | D2: Teórica | E2: Trabalho | F2: Teórica | G2: Lucro | H2: %S.B. Trab | I2: Resíduo | J2: Objetivo | L2: Jogo | M2: Estratégia | N2: Campeonato | P2: Início
B3: 1 | C3: =Diretrizes!D3 -> 100 | D3: =C3 -> 100 | E3: =IF(C3="",,IF(B3="",,C3*J3)) -> 4 | F3: =if(D3="",,D3*J3) -> 4 | H3: =IF(G3=0,,G3/C3) | I3: =if(G3="",,G3-F3) | J3: =Diretrizes!D4 -> 0.04 | P3: Fim | V3: =if(L3="","", left(L3, find(" x ",L3)-1)) | W3: =if(L3="","", TRIM(mid(L3,find(" x ",L3)+3,20)))
B4: =IF(B3<$A$1,B3+1,if($A$1="",B3+1,"")) -> 2 | C4: =IF(G3<>0,C3+G3,) | D4: =if(C4="",,D3*(1+J3)) | E4: =IF(C4="",,IF(B4="",,C4*J4)) | F4: =if(D4="",,D4*J4) | H4: =IF(G4=0,,G4/C4) | I4: =if(G4="",,G4-F4) | J4: =if(B4<>"",J3*(1-Diretrizes!D$5),) -> 0.04 | K4: =IF(AND(D4>$Q$9,D3<$Q$9),"OK","NOK") -> NOK | V4: =if(L4="","", left(L4, find(" x ",L4)-1)) | W4: =if(L4="","", TRIM(mid(L4,find(" x ",L4)+3,20)))
B5: =IF(B4<$A$1,B4+1,if($A$1="",B4+1,"")) -> 3 | C5: =IF(G4<>0,C4+G4,) | D5: =if(C5="",,D4*(1+J4)) | E5: =IF(C5="",,IF(B5="",,C5*J5)) | F5: =if(D5="",,D5*J5) | H5: =IF(G5=0,,G5/C5) | I5: =if(G5="",,G5-F5) | J5: =if(B5<>"",J4*(1-Diretrizes!D$5),) -> 0.04 | K5: =IF(AND(D5>$Q$9,D4<$Q$9),"OK","NOK") -> NOK | P5: Banca Inicial | Q5: =Diretrizes!D3 -> 100 | S5: Resíduo | T5: =SUM(I3:I32) -> 0 | V5: =if(L5="","", left(L5, find(" x ",L5)-1)) | W5: =if(L5="","", TRIM(mid(L5,find(" x ",L5)+3,20)))
B6: =IF(B5<$A$1,B5+1,if($A$1="",B5+1,"")) -> 4 | C6: =IF(G5<>0,C5+G5,) | D6: =if(C6="",,D5*(1+J5)) | E6: =IF(C6="",,IF(B6="",,C6*J6)) | F6: =if(D6="",,D6*J6) | H6: =IF(G6=0,,G6/C6) | I6: =if(G6="",,G6-F6) | J6: =if(B6<>"",J5*(1-Diretrizes!D$5),) -> 0.04 | K6: =IF(AND(D6>$Q$9,D5<$Q$9),"OK","NOK") -> NOK | P6: Banca Atual | Q6: =Q7+C3 -> 100 | V6: =if(L6="","", left(L6, find(" x ",L6)-1)) | W6: =if(L6="","", TRIM(mid(L6,find(" x ",L6)+3,20)))
B7: =IF(B6<$A$1,B6+1,if($A$1="",B6+1,"")) -> 5 | C7: =IF(G6<>0,C6+G6,) | D7: =if(C7="",,D6*(1+J6)) | E7: =IF(C7="",,IF(B7="",,C7*J7)) | F7: =if(D7="",,D7*J7) | H7: =IF(G7=0,,G7/C7) | I7: =if(G7="",,G7-F7) | J7: =if(B7<>"",J6*(1-Diretrizes!D$5),) -> 0.04 | K7: =IF(AND(D7>$Q$9,D6<$Q$9),"OK","NOK") -> NOK | P7: Lucro do ciclo | Q7: =SUM(G3:G32) -> 0 | S7: Saque | T7: =IF(G3="",,MAX(0,Q6-'Ciclo 3'!Q5)) | V7: =if(L7="","", left(L7, find(" x ",L7)-1)) | W7: =if(L7="","", TRIM(mid(L7,find(" x ",L7)+3,20)))
B8: =IF(B7<$A$1,B7+1,if($A$1="",B7+1,"")) -> 6 | C8: =IF(G7<>0,C7+G7,) | D8: =if(C8="",,D7*(1+J7)) | E8: =IF(C8="",,IF(B8="",,C8*J8)) | F8: =if(D8="",,D8*J8) | H8: =IF(G8=0,,G8/C8) | I8: =if(G8="",,G8-F8) | J8: =if(B8<>"",J7*(1-Diretrizes!D$5),) -> 0.04 | K8: =IF(AND(D8>$Q$9,D7<$Q$9),"OK","NOK") -> NOK | P8: Lucro % | Q8: =Q6/C3-1 -> 0 | V8: =if(L8="","", left(L8, find(" x ",L8)-1)) | W8: =if(L8="","", TRIM(mid(L8,find(" x ",L8)+3,20)))
B9: =IF(B8<$A$1,B8+1,if($A$1="",B8+1,"")) -> 7 | C9: =IF(G8<>0,C8+G8,) | D9: =if(C9="",,D8*(1+J8)) | E9: =IF(C9="",,IF(B9="",,C9*J9)) | F9: =if(D9="",,D9*J9) | H9: =IF(G9=0,,G9/C9) | I9: =if(G9="",,G9-F9) | J9: =if(B9<>"",J8*(1-Diretrizes!D$5),) -> 0.04 | K9: =IF(AND(D9>$Q$9,D8<$Q$9),"OK","NOK") -> NOK | V9: =if(L9="","", left(L9, find(" x ",L9)-1)) | W9: =if(L9="","", TRIM(mid(L9,find(" x ",L9)+3,20)))
B10: =IF(B9<$A$1,B9+1,if($A$1="",B9+1,"")) -> 8 | C10: =IF(G9<>0,C9+G9,) | D10: =if(C10="",,D9*(1+J9)) | E10: =IF(C10="",,IF(B10="",,C10*J10)) | F10: =if(D10="",,D10*J10) | H10: =IF(G10=0,,G10/C10) | I10: =if(G10="",,G10-F10) | J10: =if(B10<>"",J9*(1-Diretrizes!D$5),) -> 0.04 | K10: =IF(AND(D10>$Q$9,D9<$Q$9),"OK","NOK") -> NOK | P10: Parar com | Q10: =Diretrizes!D7 -> 150 | V10: =if(L10="","", left(L10, find(" x ",L10)-1)) | W10: =if(L10="","", TRIM(mid(L10,find(" x ",L10)+3,20)))
B11: =IF(B10<$A$1,B10+1,if($A$1="",B10+1,"")) -> 9 | C11: =IF(G10<>0,C10+G10,) | D11: =if(C11="",,D10*(1+J10)) | E11: =IF(C11="",,IF(B11="",,C11*J11)) | F11: =if(D11="",,D11*J11) | H11: =IF(G11=0,,G11/C11) | I11: =if(G11="",,G11-F11) | J11: =if(B11<>"",J10*(1-Diretrizes!D$5),) -> 0.04 | K11: =IF(AND(D11>$Q$9,D10<$Q$9),"OK","NOK") -> NOK | V11: =if(L11="","", left(L11, find(" x ",L11)-1)) | W11: =if(L11="","", TRIM(mid(L11,find(" x ",L11)+3,20)))
B12: =IF(B11<$A$1,B11+1,if($A$1="",B11+1,"")) -> 10 | C12: =IF(G11<>0,C11+G11,) | D12: =if(C12="",,D11*(1+J11)) | E12: =IF(C12="",,IF(B12="",,C12*J12)) | F12: =if(D12="",,D12*J12) | H12: =IF(G12=0,,G12/C12) | I12: =if(G12="",,G12-F12) | J12: =if(B12<>"",J11*(1-Diretrizes!D$5),) -> 0.04 | K12: =IF(AND(D12>$Q$9,D11<$Q$9),"OK","NOK") -> NOK | P12: Desempenho por Estratégia | V12: =if(L12="","", left(L12, find(" x ",L12)-1)) | W12: =if(L12="","", TRIM(mid(L12,find(" x ",L12)+3,20)))
B13: =IF(B12<$A$1,B12+1,if($A$1="",B12+1,"")) -> 11 | C13: =IF(G12<>0,C12+G12,) | D13: =if(C13="",,D12*(1+J12)) | E13: =IF(C13="",,IF(B13="",,C13*J13)) | F13: =if(D13="",,D13*J13) | H13: =IF(G13=0,,G13/C13) | I13: =if(G13="",,G13-F13) | J13: =if(B13<>"",J12*(1-Diretrizes!D$5),) -> 0.04 | P13: Estratégia | Q13: Valor | R13: Qt | S13: %Médio | T13: %Total | V13: =if(L13="","", left(L13, find(" x ",L13)-1)) | W13: =if(L13="","", TRIM(mid(L13,find(" x ",L13)+3,20)))
B14: =IF(B13<$A$1,B13+1,if($A$1="",B13+1,"")) -> 12 | C14: =IF(G13<>0,C13+G13,) | D14: =if(C14="",,D13*(1+J13)) | E14: =IF(C14="",,IF(B14="",,C14*J14)) | F14: =if(D14="",,D14*J14) | H14: =IF(G14=0,,G14/C14) | I14: =if(G14="",,G14-F14) | J14: =if(B14<>"",J13*(1-Diretrizes!D$5),) -> 0.04 | P14: {=sort(unique(M3:M120))} | Q14: =if(P14="","", sumif(M$3:M120,P14,G$3:G120)) | R14: =if(P14="","", countif(M$3:M120,P14)) | S14: =if(P14="","", averageif(M$3:M120,P14,H$3:H120)) | T14: =if(P14="","",Q14/sum($G$3:$G120)) | V14: =if(L14="","", left(L14, find(" x ",L14)-1)) | W14: =if(L14="","", TRIM(mid(L14,find(" x ",L14)+3,20)))
B15: =IF(B14<$A$1,B14+1,if($A$1="",B14+1,"")) | C15: =IF(G14<>0,C14+G14,) | D15: =if(C15="",,D14*(1+J14)) | E15: =IF(C15="",,IF(B15="",,C15*J15)) | F15: =if(D15="",,D15*J15) | H15: =IF(G15=0,,G15/C15) | I15: =if(G15="",,G15-F15) | J15: =if(B15<>"",J14*(1-Diretrizes!D$5),) | Q15: =if(P15="","", sumif(M$3:M121,P15,G$3:G121)) | R15: =if(P15="","", countif(M$3:M121,P15)) | S15: =if(P15="","", averageif(M$3:M121,P15,H$3:H121)) | T15: =if(P15="","",Q15/sum($G$3:$G121)) | V15: =if(L15="","", left(L15, find(" x ",L15)-1)) | W15: =if(L15="","", TRIM(mid(L15,find(" x ",L15)+3,20)))
B16: =IF(B15<$A$1,B15+1,if($A$1="",B15+1,"")) | C16: =IF(G15<>0,C15+G15,) | D16: =if(C16="",,D15*(1+J15)) | E16: =IF(C16="",,IF(B16="",,C16*J16)) | F16: =if(D16="",,D16*J16) | H16: =IF(G16=0,,G16/C16) | I16: =if(G16="",,G16-F16) | J16: =if(B16<>"",J15*(1-Diretrizes!D$5),) | Q16: =if(P16="","", sumif(M$3:M122,P16,G$3:G122)) | R16: =if(P16="","", countif(M$3:M122,P16)) | S16: =if(P16="","", averageif(M$3:M122,P16,H$3:H122)) | T16: =if(P16="","",Q16/sum($G$3:$G122)) | V16: =if(L16="","", left(L16, find(" x ",L16)-1)) | W16: =if(L16="","", TRIM(mid(L16,find(" x ",L16)+3,20)))
B17: =IF(B16<$A$1,B16+1,if($A$1="",B16+1,"")) | C17: =IF(G16<>0,C16+G16,) | D17: =if(C17="",,D16*(1+J16)) | E17: =IF(C17="",,IF(B17="",,C17*J17)) | F17: =if(D17="",,D17*J17) | H17: =IF(G17=0,,G17/C17) | I17: =if(G17="",,G17-F17) | J17: =if(B17<>"",J16*(1-Diretrizes!D$5),) | Q17: =if(P17="","", sumif(M$3:M123,P17,G$3:G123)) | R17: =if(P17="","", countif(M$3:M123,P17)) | S17: =if(P17="","", averageif(M$3:M123,P17,H$3:H123)) | T17: =if(P17="","",Q17/sum($G$3:$G123)) | V17: =if(L17="","", left(L17, find(" x ",L17)-1)) | W17: =if(L17="","", TRIM(mid(L17,find(" x ",L17)+3,20)))
B18: =IF(B17<$A$1,B17+1,if($A$1="",B17+1,"")) | C18: =IF(G17<>0,C17+G17,) | D18: =if(C18="",,D17*(1+J17)) | E18: =IF(C18="",,IF(B18="",,C18*J18)) | F18: =if(D18="",,D18*J18) | H18: =IF(G18=0,,G18/C18) | I18: =if(G18="",,G18-F18) | J18: =if(B18<>"",J17*(1-Diretrizes!D$5),) | Q18: =if(P18="","", sumif(M$3:M124,P18,G$3:G124)) | R18: =if(P18="","", countif(M$3:M124,P18)) | S18: =if(P18="","", averageif(M$3:M124,P18,H$3:H124)) | T18: =if(P18="","",Q18/sum($G$3:$G124)) | V18: =if(L18="","", left(L18, find(" x ",L18)-1)) | W18: =if(L18="","", TRIM(mid(L18,find(" x ",L18)+3,20)))
B19: =IF(B18<$A$1,B18+1,if($A$1="",B18+1,"")) | C19: =IF(G18<>0,C18+G18,) | D19: =if(C19="",,D18*(1+J18)) | E19: =IF(C19="",,IF(B19="",,C19*J19)) | F19: =if(D19="",,D19*J19) | H19: =IF(G19=0,,G19/C19) | I19: =if(G19="",,G19-F19) | J19: =if(B19<>"",J18*(1-Diretrizes!D$5),) | Q19: =if(P19="","", sumif(M$3:M125,P19,G$3:G125)) | R19: =if(P19="","", countif(M$3:M125,P19)) | S19: =if(P19="","", averageif(M$3:M125,P19,H$3:H125)) | T19: =if(P19="","",Q19/sum($G$3:$G125)) | V19: =if(L19="","", left(L19, find(" x ",L19)-1)) | W19: =if(L19="","", TRIM(mid(L19,find(" x ",L19)+3,20)))
B20: =IF(B19<$A$1,B19+1,if($A$1="",B19+1,"")) | C20: =IF(G19<>0,C19+G19,) | D20: =if(C20="",,D19*(1+J19)) | E20: =IF(C20="",,IF(B20="",,C20*J20)) | F20: =if(D20="",,D20*J20) | H20: =IF(G20=0,,G20/C20) | I20: =if(G20="",,G20-F20) | J20: =if(B20<>"",J19*(1-Diretrizes!D$5),) | Q20: =if(P20="","", sumif(M$3:M126,P20,G$3:G126)) | R20: =if(P20="","", countif(M$3:M126,P20)) | S20: =if(P20="","", averageif(M$3:M126,P20,H$3:H126)) | T20: =if(P20="","",Q20/sum($G$3:$G126)) | V20: =if(L20="","", left(L20, find(" x ",L20)-1)) | W20: =if(L20="","", TRIM(mid(L20,find(" x ",L20)+3,20)))
B21: =IF(B20<$A$1,B20+1,if($A$1="",B20+1,"")) | C21: =IF(G20<>0,C20+G20,) | D21: =if(C21="",,D20*(1+J20)) | E21: =IF(C21="",,IF(B21="",,C21*J21)) | F21: =if(D21="",,D21*J21) | H21: =IF(G21=0,,G21/C21) | I21: =if(G21="",,G21-F21) | J21: =if(B21<>"",J20*(1-Diretrizes!D$5),) | Q21: =if(P21="","", sumif(M$3:M127,P21,G$3:G127)) | R21: =if(P21="","", countif(M$3:M127,P21)) | S21: =if(P21="","", averageif(M$3:M127,P21,H$3:H127)) | T21: =if(P21="","",Q21/sum($G$3:$G127)) | V21: =if(L21="","", left(L21, find(" x ",L21)-1)) | W21: =if(L21="","", TRIM(mid(L21,find(" x ",L21)+3,20)))
B22: =IF(B21<$A$1,B21+1,if($A$1="",B21+1,"")) | C22: =IF(G21<>0,C21+G21,) | D22: =if(C22="",,D21*(1+J21)) | E22: =IF(C22="",,IF(B22="",,C22*J22)) | F22: =if(D22="",,D22*J22) | H22: =IF(G22=0,,G22/C22) | I22: =if(G22="",,G22-F22) | J22: =if(B22<>"",J21*(1-Diretrizes!D$5),) | Q22: =if(P22="","", sumif(M$3:M128,P22,G$3:G128)) | R22: =if(P22="","", countif(M$3:M128,P22)) | S22: =if(P22="","", averageif(M$3:M128,P22,H$3:H128)) | T22: =if(P22="","",Q22/sum($G$3:$G128)) | V22: =if(L22="","", left(L22, find(" x ",L22)-1)) | W22: =if(L22="","", TRIM(mid(L22,find(" x ",L22)+3,20)))
B23: =IF(B22<$A$1,B22+1,if($A$1="",B22+1,"")) | C23: =IF(G22<>0,C22+G22,) | D23: =if(C23="",,D22*(1+J22)) | E23: =IF(C23="",,IF(B23="",,C23*J23)) | F23: =if(D23="",,D23*J23) | H23: =IF(G23=0,,G23/C23) | I23: =if(G23="",,G23-F23) | J23: =if(B23<>"",J22*(1-Diretrizes!D$5),) | Q23: =if(P23="","", sumif(M$3:M129,P23,G$3:G129)) | R23: =if(P23="","", countif(M$3:M129,P23)) | S23: =if(P23="","", averageif(M$3:M129,P23,H$3:H129)) | T23: =if(P23="","",Q23/sum($G$3:$G129)) | V23: =if(L23="","", left(L23, find(" x ",L23)-1)) | W23: =if(L23="","", TRIM(mid(L23,find(" x ",L23)+3,20)))
B24: =IF(B23<$A$1,B23+1,if($A$1="",B23+1,"")) | C24: =IF(G23<>0,C23+G23,) | D24: =if(C24="",,D23*(1+J23)) | E24: =IF(C24="",,IF(B24="",,C24*J24)) | F24: =if(D24="",,D24*J24) | H24: =IF(G24=0,,G24/C24) | I24: =if(G24="",,G24-F24) | J24: =if(B24<>"",J23*(1-Diretrizes!D$5),) | Q24: =if(P24="","", sumif(M$3:M130,P24,G$3:G130)) | R24: =if(P24="","", countif(M$3:M130,P24)) | S24: =if(P24="","", averageif(M$3:M130,P24,H$3:H130)) | T24: =if(P24="","",Q24/sum($G$3:$G130)) | V24: =if(L24="","", left(L24, find(" x ",L24)-1)) | W24: =if(L24="","", TRIM(mid(L24,find(" x ",L24)+3,20)))
B25: =IF(B24<$A$1,B24+1,if($A$1="",B24+1,"")) | C25: =IF(G24<>0,C24+G24,) | D25: =if(C25="",,D24*(1+J24)) | E25: =IF(C25="",,IF(B25="",,C25*J25)) | F25: =if(D25="",,D25*J25) | H25: =IF(G25=0,,G25/C25) | I25: =if(G25="",,G25-F25) | J25: =if(B25<>"",J24*(1-Diretrizes!D$5),) | P25: Desempenho por Campeonato | V25: =if(L25="","", left(L25, find(" x ",L25)-1)) | W25: =if(L25="","", TRIM(mid(L25,find(" x ",L25)+3,20)))
B26: =IF(B25<$A$1,B25+1,if($A$1="",B25+1,"")) | C26: =IF(G25<>0,C25+G25,) | D26: =if(C26="",,D25*(1+J25)) | E26: =IF(C26="",,IF(B26="",,C26*J26)) | F26: =if(D26="",,D26*J26) | H26: =IF(G26=0,,G26/C26) | I26: =if(G26="",,G26-F26) | J26: =if(B26<>"",J25*(1-Diretrizes!D$5),) | P26: Estratégia | Q26: Valor | R26: Qt | S26: %Médio | T26: %Total | V26: =if(L26="","", left(L26, find(" x ",L26)-1)) | W26: =if(L26="","", TRIM(mid(L26,find(" x ",L26)+3,20)))
B27: =IF(B26<$A$1,B26+1,if($A$1="",B26+1,"")) | C27: =IF(G26<>0,C26+G26,) | D27: =if(C27="",,D26*(1+J26)) | E27: =IF(C27="",,IF(B27="",,C27*J27)) | F27: =if(D27="",,D27*J27) | H27: =IF(G27=0,,G27/C27) | I27: =if(G27="",,G27-F27) | J27: =if(B27<>"",J26*(1-Diretrizes!D$5),) | P27: {=sort(unique(N3:N120))} | Q27: =if(P27="","", sumif(N$3:N120,P27,G$3:G120)) | R27: =if(P27="","", countif(N$3:N120,P27)) | S27: =if(P27="","", averageif(N$3:N120,P27,H$3:H120)) | T27: =if(P27="","",Q27/sum($G$3:$G120)) | V27: =if(L27="","", left(L27, find(" x ",L27)-1)) | W27: =if(L27="","", TRIM(mid(L27,find(" x ",L27)+3,20)))
B28: =IF(B27<$A$1,B27+1,if($A$1="",B27+1,"")) | C28: =IF(G27<>0,C27+G27,) | D28: =if(C28="",,D27*(1+J27)) | E28: =IF(C28="",,IF(B28="",,C28*J28)) | F28: =if(D28="",,D28*J28) | H28: =IF(G28=0,,G28/C28) | I28: =if(G28="",,G28-F28) | J28: =if(B28<>"",J27*(1-Diretrizes!D$5),) | Q28: =if(P28="","", sumif(N$3:N121,P28,G$3:G121)) | R28: =if(P28="","", countif(N$3:N121,P28)) | S28: =if(P28="","", averageif(N$3:N121,P28,H$3:H121)) | T28: =if(P28="","",Q28/sum($G$3:$G121)) | V28: =if(L28="","", left(L28, find(" x ",L28)-1)) | W28: =if(L28="","", TRIM(mid(L28,find(" x ",L28)+3,20)))
B29: =IF(B28<$A$1,B28+1,if($A$1="",B28+1,"")) | C29: =IF(G28<>0,C28+G28,) | D29: =if(C29="",,D28*(1+J28)) | E29: =IF(C29="",,IF(B29="",,C29*J29)) | F29: =if(D29="",,D29*J29) | H29: =IF(G29=0,,G29/C29) | I29: =if(G29="",,G29-F29) | J29: =if(B29<>"",J28*(1-Diretrizes!D$5),) | Q29: =if(P29="","", sumif(N$3:N122,P29,G$3:G122)) | R29: =if(P29="","", countif(N$3:N122,P29)) | S29: =if(P29="","", averageif(N$3:N122,P29,H$3:H122)) | T29: =if(P29="","",Q29/sum($G$3:$G122)) | V29: =if(L29="","", left(L29, find(" x ",L29)-1)) | W29: =if(L29="","", TRIM(mid(L29,find(" x ",L29)+3,20)))
B30: =IF(B29<$A$1,B29+1,if($A$1="",B29+1,"")) | C30: =IF(G29<>0,C29+G29,) | D30: =if(C30="",,D29*(1+J29)) | E30: =IF(C30="",,IF(B30="",,C30*J30)) | F30: =if(D30="",,D30*J30) | H30: =IF(G30=0,,G30/C30) | I30: =if(G30="",,G30-F30) | J30: =if(B30<>"",J29*(1-Diretrizes!D$5),) | Q30: =if(P30="","", sumif(N$3:N123,P30,G$3:G123)) | R30: =if(P30="","", countif(N$3:N123,P30)) | S30: =if(P30="","", averageif(N$3:N123,P30,H$3:H123)) | T30: =if(P30="","",Q30/sum($G$3:$G123)) | V30: =if(L30="","", left(L30, find(" x ",L30)-1)) | W30: =if(L30="","", TRIM(mid(L30,find(" x ",L30)+3,20)))
B31: =IF(B30<$A$1,B30+1,if($A$1="",B30+1,"")) | C31: =IF(G30<>0,C30+G30,) | D31: =if(C31="",,D30*(1+J30)) | E31: =IF(C31="",,IF(B31="",,C31*J31)) | F31: =if(D31="",,D31*J31) | H31: =IF(G31=0,,G31/C31) | I31: =if(G31="",,G31-F31) | J31: =if(B31<>"",J30*(1-Diretrizes!D$5),) | Q31: =if(P31="","", sumif(N$3:N124,P31,G$3:G124)) | R31: =if(P31="","", countif(N$3:N124,P31)) | S31: =if(P31="","", averageif(N$3:N124,P31,H$3:H124)) | T31: =if(P31="","",Q31/sum($G$3:$G124)) | V31: =if(L31="","", left(L31, find(" x ",L31)-1)) | W31: =if(L31="","", TRIM(mid(L31,find(" x ",L31)+3,20)))
B32: =IF(B31<$A$1,B31+1,if($A$1="",B31+1,"")) | C32: =IF(G31<>0,C31+G31,) | D32: =if(C32="",,D31*(1+J31)) | E32: =IF(C32="",,IF(B32="",,C32*J32)) | F32: =if(D32="",,D32*J32) | H32: =IF(G32=0,,G32/C32) | I32: =if(G32="",,G32-F32) | J32: =if(B32<>"",J31*(1-Diretrizes!D$5),) | Q32: =if(P32="","", sumif(N$3:N125,P32,G$3:G125)) | R32: =if(P32="","", countif(N$3:N125,P32)) | S32: =if(P32="","", averageif(N$3:N125,P32,H$3:H125)) | T32: =if(P32="","",Q32/sum($G$3:$G125)) | V32: =if(L32="","", left(L32, find(" x ",L32)-1)) | W32: =if(L32="","", TRIM(mid(L32,find(" x ",L32)+3,20)))
C33: =IF(G32<>0,C32+G32,) | D33: =if(C33="",,D32*(1+J32)) | Q33: =if(P33="","", sumif(N$3:N126,P33,G$3:G126)) | R33: =if(P33="","", countif(N$3:N126,P33)) | S33: =if(P33="","", averageif(N$3:N126,P33,H$3:H126)) | T33: =if(P33="","",Q33/sum($G$3:$G126)) | V33: =if(L33="","", left(L33, find(" x ",L33)-1)) | W33: =if(L33="","", TRIM(mid(L33,find(" x ",L33)+3,20)))
Q34: =if(P34="","", sumif(N$3:N127,P34,G$3:G127)) | R34: =if(P34="","", countif(N$3:N127,P34)) | S34: =if(P34="","", averageif(N$3:N127,P34,H$3:H127)) | T34: =if(P34="","",Q34/sum($G$3:$G127)) | V34: =if(L34="","", left(L34, find(" x ",L34)-1)) | W34: =if(L34="","", TRIM(mid(L34,find(" x ",L34)+3,20)))
Q35: =if(P35="","", sumif(N$3:N128,P35,G$3:G128)) | R35: =if(P35="","", countif(N$3:N128,P35)) | S35: =if(P35="","", averageif(N$3:N128,P35,H$3:H128)) | T35: =if(P35="","",Q35/sum($G$3:$G128)) | V35: =if(L35="","", left(L35, find(" x ",L35)-1)) | W35: =if(L35="","", TRIM(mid(L35,find(" x ",L35)+3,20)))
Q36: =if(P36="","", sumif(N$3:N129,P36,G$3:G129)) | R36: =if(P36="","", countif(N$3:N129,P36)) | S36: =if(P36="","", averageif(N$3:N129,P36,H$3:H129)) | T36: =if(P36="","",Q36/sum($G$3:$G129)) | V36: =if(L36="","", left(L36, find(" x ",L36)-1)) | W36: =if(L36="","", TRIM(mid(L36,find(" x ",L36)+3,20)))
Q37: =if(P37="","", sumif(N$3:N130,P37,G$3:G130)) | R37: =if(P37="","", countif(N$3:N130,P37)) | S37: =if(P37="","", averageif(N$3:N130,P37,H$3:H130)) | T37: =if(P37="","",Q37/sum($G$3:$G130)) | V37: =if(L37="","", left(L37, find(" x ",L37)-1)) | W37: =if(L37="","", TRIM(mid(L37,find(" x ",L37)+3,20)))
P38: Desempenho por Clube | V38: =if(L38="","", left(L38, find(" x ",L38)-1)) | W38: =if(L38="","", TRIM(mid(L38,find(" x ",L38)+3,20)))
P39: Clube | Q39: Valor | R39: Qt | S39: %Médio | T39: %Total | V39: =if(L39="","", left(L39, find(" x ",L39)-1)) | W39: =if(L39="","", TRIM(mid(L39,find(" x ",L39)+3,20)))
P40: {=sort(UNIQUE({V3:V120;W3:W120}))} | V40: =if(L40="","", left(L40, find(" x ",L40)-1)) | W40: =if(L40="","", TRIM(mid(L40,find(" x ",L40)+3,20)))
...

Sheet Ciclo 3
A1: =IF(Diretrizes!J3<2,"",Diretrizes!J3) -> 12 | C1: Banca | D1: Banca | E1: Obj/Banca | F1: Obj./Banca
B2: Jogo | C2: Trabalho | D2: Teórica | E2: Trabalho | F2: Teórica | G2: Lucro | H2: %S.B. Trab | I2: Resíduo | J2: Objetivo | L2: Jogo | M2: Estratégia | N2: Campeonato | P2: Início
B3: 1 | C3: =Diretrizes!E3 -> 125 | D3: =C3 -> 125 | E3: =IF(C3="",,IF(B3="",,C3*J3)) -> 5 | F3: =if(D3="",,D3*J3) -> 5 | H3: =IF(G3=0,,G3/C3) | I3: =if(G3="",,G3-F3) | J3: =Diretrizes!E4 -> 0.04 | P3: Fim | V3: =if(L3="","", left(L3, find(" x ",L3)-1)) | W3: =if(L3="","", TRIM(mid(L3,find(" x ",L3)+3,20)))
B4: =IF(B3<$A$1,B3+1,if($A$1="",B3+1,"")) -> 2 | C4: =IF(G3<>0,C3+G3,) | D4: =if(C4="",,D3*(1+J3)) | E4: =IF(C4="",,IF(B4="",,C4*J4)) | F4: =if(D4="",,D4*J4) | H4: =IF(G4=0,,G4/C4) | I4: =if(G4="",,G4-F4) | J4: =if(B4<>"",J3*(1-Diretrizes!E$5),) -> 0.04 | K4: =IF(AND(D4>$Q$9,D3<$Q$9),"OK","NOK") -> NOK | V4: =if(L4="","", left(L4, find(" x ",L4)-1)) | W4: =if(L4="","", TRIM(mid(L4,find(" x ",L4)+3,20)))
B5: =IF(B4<$A$1,B4+1,if($A$1="",B4+1,"")) -> 3 | C5: =IF(G4<>0,C4+G4,) | D5: =if(C5="",,D4*(1+J4)) | E5: =IF(C5="",,IF(B5="",,C5*J5)) | F5: =if(D5="",,D5*J5) | H5: =IF(G5=0,,G5/C5) | I5: =if(G5="",,G5-F5) | J5: =if(B5<>"",J4*(1-Diretrizes!E$5),) -> 0.04 | K5: =IF(AND(D5>$Q$9,D4<$Q$9),"OK","NOK") -> NOK | P5: Banca Inicial | Q5: =Diretrizes!E3 -> 125 | S5: Resíduo | T5: =SUM(I3:I32) -> 0 | V5: =if(L5="","", left(L5, find(" x ",L5)-1)) | W5: =if(L5="","", TRIM(mid(L5,find(" x ",L5)+3,20)))
B6: =IF(B5<$A$1,B5+1,if($A$1="",B5+1,"")) -> 4 | C6: =IF(G5<>0,C5+G5,) | D6: =if(C6="",,D5*(1+J5)) | E6: =IF(C6="",,IF(B6="",,C6*J6)) | F6: =if(D6="",,D6*J6) | H6: =IF(G6=0,,G6/C6) | I6: =if(G6="",,G6-F6) | J6: =if(B6<>"",J5*(1-Diretrizes!E$5),) -> 0.04 | K6: =IF(AND(D6>$Q$9,D5<$Q$9),"OK","NOK") -> NOK | P6: Banca Atual | Q6: =Q7+C3 -> 125 | V6: =if(L6="","", left(L6, find(" x ",L6)-1)) | W6: =if(L6="","", TRIM(mid(L6,find(" x ",L6)+3,20)))
B7: =IF(B6<$A$1,B6+1,if($A$1="",B6+1,"")) -> 5 | C7: =IF(G6<>0,C6+G6,) | D7: =if(C7="",,D6*(1+J6)) | E7: =IF(C7="",,IF(B7="",,C7*J7)) | F7: =if(D7="",,D7*J7) | H7: =IF(G7=0,,G7/C7) | I7: =if(G7="",,G7-F7) | J7: =if(B7<>"",J6*(1-Diretrizes!E$5),) -> 0.04 | K7: =IF(AND(D7>$Q$9,D6<$Q$9),"OK","NOK") -> NOK | P7: Lucro do ciclo | Q7: =SUM(G3:G32) -> 0 | S7: Saque | T7: =IF(G3="",,MAX(0,Q6-'Ciclo 4'!Q5)) | V7: =if(L7="","", left(L7, find(" x ",L7)-1)) | W7: =if(L7="","", TRIM(mid(L7,find(" x ",L7)+3,20)))
B8: =IF(B7<$A$1,B7+1,if($A$1="",B7+1,"")) -> 6 | C8: =IF(G7<>0,C7+G7,) | D8: =if(C8="",,D7*(1+J7)) | E8: =IF(C8="",,IF(B8="",,C8*J8)) | F8: =if(D8="",,D8*J8) | H8: =IF(G8=0,,G8/C8) | I8: =if(G8="",,G8-F8) | J8: =if(B8<>"",J7*(1-Diretrizes!E$5),) -> 0.04 | K8: =IF(AND(D8>$Q$9,D7<$Q$9),"OK","NOK") -> NOK | P8: Lucro % | Q8: =Q6/C3-1 -> 0 | V8: =if(L8="","", left(L8, find(" x ",L8)-1)) | W8: =if(L8="","", TRIM(mid(L8,find(" x ",L8)+3,20)))
B9: =IF(B8<$A$1,B8+1,if($A$1="",B8+1,"")) -> 7 | C9: =IF(G8<>0,C8+G8,) | D9: =if(C9="",,D8*(1+J8)) | E9: =IF(C9="",,IF(B9="",,C9*J9)) | F9: =if(D9="",,D9*J9) | H9: =IF(G9=0,,G9/C9) | I9: =if(G9="",,G9-F9) | J9: =if(B9<>"",J8*(1-Diretrizes!E$5),) -> 0.04 | K9: =IF(AND(D9>$Q$9,D8<$Q$9),"OK","NOK") -> NOK | V9: =if(L9="","", left(L9, find(" x ",L9)-1)) | W9: =if(L9="","", TRIM(mid(L9,find(" x ",L9)+3,20)))
B10: =IF(B9<$A$1,B9+1,if($A$1="",B9+1,"")) -> 8 | C10: =IF(G9<>0,C9+G9,) | D10: =if(C10="",,D9*(1+J9)) | E10: =IF(C10="",,IF(B10="",,C10*J10)) | F10: =if(D10="",,D10*J10) | H10: =IF(G10=0,,G10/C10) | I10: =if(G10="",,G10-F10) | J10: =if(B10<>"",J9*(1-Diretrizes!E$5),) -> 0.04 | K10: =IF(AND(D10>$Q$9,D9<$Q$9),"OK","NOK") -> NOK | P10: Parar com | Q10: =Diretrizes!E7 -> 187.5 | V10: =if(L10="","", left(L10, find(" x ",L10)-1)) | W10: =if(L10="","", TRIM(mid(L10,find(" x ",L10)+3,20)))
B11: =IF(B10<$A$1,B10+1,if($A$1="",B10+1,"")) -> 9 | C11: =IF(G10<>0,C10+G10,) | D11: =if(C11="",,D10*(1+J10)) | E11: =IF(C11="",,IF(B11="",,C11*J11)) | F11: =if(D11="",,D11*J11) | H11: =IF(G11=0,,G11/C11) | I11: =if(G11="",,G11-F11) | J11: =if(B11<>"",J10*(1-Diretrizes!E$5),) -> 0.04 | K11: =IF(AND(D11>$Q$9,D10<$Q$9),"OK","NOK") -> NOK | V11: =if(L11="","", left(L11, find(" x ",L11)-1)) | W11: =if(L11="","", TRIM(mid(L11,find(" x ",L11)+3,20)))
B12: =IF(B11<$A$1,B11+1,if($A$1="",B11+1,"")) -> 10 | C12: =IF(G11<>0,C11+G11,) | D12: =if(C12="",,D11*(1+J11)) | E12: =IF(C12="",,IF(B12="",,C12*J12)) | F12: =if(D12="",,D12*J12) | H12: =IF(G12=0,,G12/C12) | I12: =if(G12="",,G12-F12) | J12: =if(B12<>"",J11*(1-Diretrizes!E$5),) -> 0.04 | K12: =IF(AND(D12>$Q$9,D11<$Q$9),"OK","NOK") -> NOK | P12: Desempenho por Estratégia | V12: =if(L12="","", left(L12, find(" x ",L12)-1)) | W12: =if(L12="","", TRIM(mid(L12,find(" x ",L12)+3,20)))
B13: =IF(B12<$A$1,B12+1,if($A$1="",B12+1,"")) -> 11 | C13: =IF(G12<>0,C12+G12,) | D13: =if(C13="",,D12*(1+J12)) | E13: =IF(C13="",,IF(B13="",,C13*J13)) | F13: =if(D13="",,D13*J13) | H13: =IF(G13=0,,G13/C13) | I13: =if(G13="",,G13-F13) | J13: =if(B13<>"",J12*(1-Diretrizes!E$5),) -> 0.04 | P13: Estratégia | Q13: Valor | R13: Qt | S13: %Médio | T13: %Total | V13: =if(L13="","", left(L13, find(" x ",L13)-1)) | W13: =if(L13="","", TRIM(mid(L13,find(" x ",L13)+3,20)))
B14: =IF(B13<$A$1,B13+1,if($A$1="",B13+1,"")) -> 12 | C14: =IF(G13<>0,C13+G13,) | D14: =if(C14="",,D13*(1+J13)) | E14: =IF(C14="",,IF(B14="",,C14*J14)) | F14: =if(D14="",,D14*J14) | H14: =IF(G14=0,,G14/C14) | I14: =if(G14="",,G14-F14) | J14: =if(B14<>"",J13*(1-Diretrizes!E$5),) -> 0.04 | P14: {=sort(unique(M3:M120))} | Q14: =if(P14="","", sumif(M$3:M120,P14,G$3:G120)) | R14: =if(P14="","", countif(M$3:M120,P14)) | S14: =if(P14="","", averageif(M$3:M120,P14,H$3:H120)) | T14: =if(P14="","",Q14/sum($G$3:$G120)) | V14: =if(L14="","", left(L14, find(" x ",L14)-1)) | W14: =if(L14="","", TRIM(mid(L14,find(" x ",L14)+3,20)))
B15: =IF(B14<$A$1,B14+1,if($A$1="",B14+1,"")) | C15: =IF(G14<>0,C14+G14,) | D15: =if(C15="",,D14*(1+J14)) | E15: =IF(C15="",,IF(B15="",,C15*J15)) | F15: =if(D15="",,D15*J15) | H15: =IF(G15=0,,G15/C15) | I15: =if(G15="",,G15-F15) | J15: =if(B15<>"",J14*(1-Diretrizes!E$5),) | Q15: =if(P15="","", sumif(M$3:M121,P15,G$3:G121)) | R15: =if(P15="","", countif(M$3:M121,P15)) | S15: =if(P15="","", averageif(M$3:M121,P15,H$3:H121)) | T15: =if(P15="","",Q15/sum($G$3:$G121)) | V15: =if(L15="","", left(L15, find(" x ",L15)-1)) | W15: =if(L15="","", TRIM(mid(L15,find(" x ",L15)+3,20)))
B16: =IF(B15<$A$1,B15+1,if($A$1="",B15+1,"")) | C16: =IF(G15<>0,C15+G15,) | D16: =if(C16="",,D15*(1+J15)) | E16: =IF(C16="",,IF(B16="",,C16*J16)) | F16: =if(D16="",,D16*J16) | H16: =IF(G16=0,,G16/C16) | I16: =if(G16="",,G16-F16) | J16: =if(B16<>"",J15*(1-Diretrizes!E$5),) | Q16: =if(P16="","", sumif(M$3:M122,P16,G$3:G122)) | R16: =if(P16="","", countif(M$3:M122,P16)) | S16: =if(P16="","", averageif(M$3:M122,P16,H$3:H122)) | T16: =if(P16="","",Q16/sum($G$3:$G122)) | V16: =if(L16="","", left(L16, find(" x ",L16)-1)) | W16: =if(L16="","", TRIM(mid(L16,find(" x ",L16)+3,20)))
B17: =IF(B16<$A$1,B16+1,if($A$1="",B16+1,"")) | C17: =IF(G16<>0,C16+G16,) | D17: =if(C17="",,D16*(1+J16)) | E17: =IF(C17="",,IF(B17="",,C17*J17)) | F17: =if(D17="",,D17*J17) | H17: =IF(G17=0,,G17/C17) | I17: =if(G17="",,G17-F17) | J17: =if(B17<>"",J16*(1-Diretrizes!E$5),) | Q17: =if(P17="","", sumif(M$3:M123,P17,G$3:G123)) | R17: =if(P17="","", countif(M$3:M123,P17)) | S17: =if(P17="","", averageif(M$3:M123,P17,H$3:H123)) | T17: =if(P17="","",Q17/sum($G$3:$G123)) | V17: =if(L17="","", left(L17, find(" x ",L17)-1)) | W17: =if(L17="","", TRIM(mid(L17,find(" x ",L17)+3,20)))
B18: =IF(B17<$A$1,B17+1,if($A$1="",B17+1,"")) | C18: =IF(G17<>0,C17+G17,) | D18: =if(C18="",,D17*(1+J17)) | E18: =IF(C18="",,IF(B18="",,C18*J18)) | F18: =if(D18="",,D18*J18) | H18: =IF(G18=0,,G18/C18) | I18: =if(G18="",,G18-F18) | J18: =if(B18<>"",J17*(1-Diretrizes!E$5),) | Q18: =if(P18="","", sumif(M$3:M124,P18,G$3:G124)) | R18: =if(P18="","", countif(M$3:M124,P18)) | S18: =if(P18="","", averageif(M$3:M124,P18,H$3:H124)) | T18: =if(P18="","",Q18/sum($G$3:$G124)) | V18: =if(L18="","", left(L18, find(" x ",L18)-1)) | W18: =if(L18="","", TRIM(mid(L18,find(" x ",L18)+3,20)))
B19: =IF(B18<$A$1,B18+1,if($A$1="",B18+1,"")) | C19: =IF(G18<>0,C18+G18,) | D19: =if(C19="",,D18*(1+J18)) | E19: =IF(C19="",,IF(B19="",,C19*J19)) | F19: =if(D19="",,D19*J19) | H19: =IF(G19=0,,G19/C19) | I19: =if(G19="",,G19-F19) | J19: =if(B19<>"",J18*(1-Diretrizes!E$5),) | Q19: =if(P19="","", sumif(M$3:M125,P19,G$3:G125)) | R19: =if(P19="","", countif(M$3:M125,P19)) | S19: =if(P19="","", averageif(M$3:M125,P19,H$3:H125)) | T19: =if(P19="","",Q19/sum($G$3:$G125)) | V19: =if(L19="","", left(L19, find(" x ",L19)-1)) | W19: =if(L19="","", TRIM(mid(L19,find(" x ",L19)+3,20)))
B20: =IF(B19<$A$1,B19+1,if($A$1="",B19+1,"")) | C20: =IF(G19<>0,C19+G19,) | D20: =if(C20="",,D19*(1+J19)) | E20: =IF(C20="",,IF(B20="",,C20*J20)) | F20: =if(D20="",,D20*J20) | H20: =IF(G20=0,,G20/C20) | I20: =if(G20="",,G20-F20) | J20: =if(B20<>"",J19*(1-Diretrizes!E$5),) | Q20: =if(P20="","", sumif(M$3:M126,P20,G$3:G126)) | R20: =if(P20="","", countif(M$3:M126,P20)) | S20: =if(P20="","", averageif(M$3:M126,P20,H$3:H126)) | T20: =if(P20="","",Q20/sum($G$3:$G126)) | V20: =if(L20="","", left(L20, find(" x ",L20)-1)) | W20: =if(L20="","", TRIM(mid(L20,find(" x ",L20)+3,20)))
